Workbook

Sheet Dashboard
A1: Dashboard — Portefólio
A3: Ano corrente | B3: 2026
A4: Mês mais recente com dados | B4: =_xlfn.MAXIFS(Dados!$C$2:$C$1000,Dados!$A$2:$A$1000,$B$3) -> 8
A6: Conta Principal | D6: Numerário (dinheiro em casa) | G6: Criptoativos (fora da alocação de investimentos)
A7: Saldo do mês mais recente | B7: =SUMIFS(Dados!$F$2:$F$1000,Dados!$D$2:$D$1000,"Conta Principal",Dados!$A$2:$A$1000,$B$3,Dados!$C$2:$C$1000,$B$4) -> 1969.12 | D7: Saldo do mês mais recente | E7: =SUMIFS(Dados!$F$2:$F$1000,Dados!$D$2:$D$1000,"Numerário",Dados!$A$2:$A$1000,$B$3,Dados!$C$2:$C$1000,$B$4) -> 10 | G7: Saldo do mês mais recente | H7: =SUMIFS(Dados!$F$2:$F$1000,Dados!$D$2:$D$1000,"Criptoativo",Dados!$A$2:$A$1000,$B$3,Dados!$C$2:$C$1000,$B$4) -> 38
A8: Média do saldo (todos os meses registados) | B8: =AVERAGEIFS(Dados!$F$2:$F$1000,Dados!$D$2:$D$1000,"Conta Principal",Dados!$A$2:$A$1000,$B$3) -> 2381.3329
A11: Evolução mensal (ano corrente)
A12: Mês | B12: Património Total | C12: Conta Principal | D12: Investimentos | E12: Numerário | F12: Criptoativos
A13: Janeiro | B13: =IF(COUNTIFS(Dados!$A$2:$A$1000,$B$3,Dados!$C$2:$C$1000,1)=0,"",SUM(C13:F13)) -> 40732.62 | C13: =IF(COUNTIFS(Dados!$A$2:$A$1000,$B$3,Dados!$C$2:$C$1000,1)=0,"",SUMIFS(Dados!$F$2:$F$1000,Dados!$D$2:$D$1000,"Conta Principal",Dados!$A$2:$A$1000,$B$3,Dados!$C$2:$C$1000,1)) -> 1670.18 | D13: =IF(COUNTIFS(Dados!$A$2:$A$1000,$B$3,Dados!$C$2:$C$1000,1)=0,"",SUMIFS(Dados!$F$2:$F$1000,Dados!$D$2:$D$1000,"Investimento",Dados!$A$2:$A$1000,$B$3,Dados!$C$2:$C$1000,1)) -> 38557.32 | E13: =IF(COUNTIFS(Dados!$A$2:$A$1000,$B$3,Dados!$C$2:$C$1000,1)=0,"",SUMIFS(Dados!$F$2:$F$1000,Dados!$D$2:$D$1000,"Numerário",Dados!$A$2:$A$1000,$B$3,Dados!$C$2:$C$1000,1)) -> 470 | F13: =IF(COUNTIFS(Dados!$A$2:$A$1000,$B$3,Dados!$C$2:$C$1000,1)=0,"",SUMIFS(Dados!$F$2:$F$1000,Dados!$D$2:$D$1000,"Criptoativo",Dados!$A$2:$A$1000,$B$3,Dados!$C$2:$C$1000,1)) -> 35.12
A14: Fevereiro | B14: =IF(COUNTIFS(Dados!$A$2:$A$1000,$B$3,Dados!$C$2:$C$1000,2)=0,"",SUM(C14:F14)) -> 38134.09 | C14: =IF(COUNTIFS(Dados!$A$2:$A$1000,$B$3,Dados!$C$2:$C$1000,2)=0,"",SUMIFS(Dados!$F$2:$F$1000,Dados!$D$2:$D$1000,"Conta Principal",Dados!$A$2:$A$1000,$B$3,Dados!$C$2:$C$1000,2)) -> 2628.38 | D14: =IF(COUNTIFS(Dados!$A$2:$A$1000,$B$3,Dados!$C$2:$C$1000,2)=0,"",SUMIFS(Dados!$F$2:$F$1000,Dados!$D$2:$D$1000,"Investimento",Dados!$A$2:$A$1000,$B$3,Dados!$C$2:$C$1000,2)) -> 35105.66 | E14: =IF(COUNTIFS(Dados!$A$2:$A$1000,$B$3,Dados!$C$2:$C$1000,2)=0,"",SUMIFS(Dados!$F$2:$F$1000,Dados!$D$2:$D$1000,"Numerário",Dados!$A$2:$A$1000,$B$3,Dados!$C$2:$C$1000,2)) -> 370 | F14: =IF(COUNTIFS(Dados!$A$2:$A$1000,$B$3,Dados!$C$2:$C$1000,2)=0,"",SUMIFS(Dados!$F$2:$F$1000,Dados!$D$2:$D$1000,"Criptoativo",Dados!$A$2:$A$1000,$B$3,Dados!$C$2:$C$1000,2)) -> 30.05
A15: Março | B15: =IF(COUNTIFS(Dados!$A$2:$A$1000,$B$3,Dados!$C$2:$C$1000,3)=0,"",SUM(C15:F15)) -> 36014.37 | C15: =IF(COUNTIFS(Dados!$A$2:$A$1000,$B$3,Dados!$C$2:$C$1000,3)=0,"",SUMIFS(Dados!$F$2:$F$1000,Dados!$D$2:$D$1000,"Conta Principal",Dados!$A$2:$A$1000,$B$3,Dados!$C$2:$C$1000,3)) -> 2675.51 | D15: =IF(COUNTIFS(Dados!$A$2:$A$1000,$B$3,Dados!$C$2:$C$1000,3)=0,"",SUMIFS(Dados!$F$2:$F$1000,Dados!$D$2:$D$1000,"Investimento",Dados!$A$2:$A$1000,$B$3,Dados!$C$2:$C$1000,3)) -> 32977.86 | E15: =IF(COUNTIFS(Dados!$A$2:$A$1000,$B$3,Dados!$C$2:$C$1000,3)=0,"",SUMIFS(Dados!$F$2:$F$1000,Dados!$D$2:$D$1000,"Numerário",Dados!$A$2:$A$1000,$B$3,Dados!$C$2:$C$1000,3)) -> 330 | F15: =IF(COUNTIFS(Dados!$A$2:$A$1000,$B$3,Dados!$C$2:$C$1000,3)=0,"",SUMIFS(Dados!$F$2:$F$1000,Dados!$D$2:$D$1000,"Criptoativo",Dados!$A$2:$A$1000,$B$3,Dados!$C$2:$C$1000,3)) -> 31
A16: Abril | B16: =IF(COUNTIFS(Dados!$A$2:$A$1000,$B$3,Dados!$C$2:$C$1000,4)=0,"",SUM(C16:F16)) -> 37317.11 | C16: =IF(COUNTIFS(Dados!$A$2:$A$1000,$B$3,Dados!$C$2:$C$1000,4)=0,"",SUMIFS(Dados!$F$2:$F$1000,Dados!$D$2:$D$1000,"Conta Principal",Dados!$A$2:$A$1000,$B$3,Dados!$C$2:$C$1000,4)) -> 2561.59 | D16: =IF(COUNTIFS(Dados!$A$2:$A$1000,$B$3,Dados!$C$2:$C$1000,4)=0,"",SUMIFS(Dados!$F$2:$F$1000,Dados!$D$2:$D$1000,"Investimento",Dados!$A$2:$A$1000,$B$3,Dados!$C$2:$C$1000,4)) -> 34630.52 | E16: =IF(COUNTIFS(Dados!$A$2:$A$1000,$B$3,Dados!$C$2:$C$1000,4)=0,"",SUMIFS(Dados!$F$2:$F$1000,Dados!$D$2:$D$1000,"Numerário",Dados!$A$2:$A$1000,$B$3,Dados!$C$2:$C$1000,4)) -> 90 | F16: =IF(COUNTIFS(Dados!$A$2:$A$1000,$B$3,Dados!$C$2:$C$1000,4)=0,"",SUMIFS(Dados!$F$2:$F$1000,Dados!$D$2:$D$1000,"Criptoativo",Dados!$A$2:$A$1000,$B$3,Dados!$C$2:$C$1000,4)) -> 35
A17: Maio | B17: =IF(COUNTIFS(Dados!$A$2:$A$1000,$B$3,Dados!$C$2:$C$1000,5)=0,"",SUM(C17:F17)) -> 38051.89 | C17: =IF(COUNTIFS(Dados!$A$2:$A$1000,$B$3,Dados!$C$2:$C$1000,5)=0,"",SUMIFS(Dados!$F$2:$F$1000,Dados!$D$2:$D$1000,"Conta Principal",Dados!$A$2:$A$1000,$B$3,Dados!$C$2:$C$1000,5)) -> 1786.89 | D17: =IF(COUNTIFS(Dados!$A$2:$A$1000,$B$3,Dados!$C$2:$C$1000,5)=0,"",SUMIFS(Dados!$F$2:$F$1000,Dados!$D$2:$D$1000,"Investimento",Dados!$A$2:$A$1000,$B$3,Dados!$C$2:$C$1000,5)) -> 36152 | E17: =IF(COUNTIFS(Dados!$A$2:$A$1000,$B$3,Dados!$C$2:$C$1000,5)=0,"",SUMIFS(Dados!$F$2:$F$1000,Dados!$D$2:$D$1000,"Numerário",Dados!$A$2:$A$1000,$B$3,Dados!$C$2:$C$1000,5)) -> 80 | F17: =IF(COUNTIFS(Dados!$A$2:$A$1000,$B$3,Dados!$C$2:$C$1000,5)=0,"",SUMIFS(Dados!$F$2:$F$1000,Dados!$D$2:$D$1000,"Criptoativo",Dados!$A$2:$A$1000,$B$3,Dados!$C$2:$C$1000,5)) -> 33
A18: Junho | B18: =IF(COUNTIFS(Dados!$A$2:$A$1000,$B$3,Dados!$C$2:$C$1000,6)=0,"",SUM(C18:F18)) | C18: =IF(COUNTIFS(Dados!$A$2:$A$1000,$B$3,Dados!$C$2:$C$1000,6)=0,"",SUMIFS(Dados!$F$2:$F$1000,Dados!$D$2:$D$1000,"Conta Principal",Dados!$A$2:$A$1000,$B$3,Dados!$C$2:$C$1000,6)) | D18: =IF(COUNTIFS(Dados!$A$2:$A$1000,$B$3,Dados!$C$2:$C$1000,6)=0,"",SUMIFS(Dados!$F$2:$F$1000,Dados!$D$2:$D$1000,"Investimento",Dados!$A$2:$A$1000,$B$3,Dados!$C$2:$C$1000,6)) | E18: =IF(COUNTIFS(Dados!$A$2:$A$1000,$B$3,Dados!$C$2:$C$1000,6)=0,"",SUMIFS(Dados!$F$2:$F$1000,Dados!$D$2:$D$1000,"Numerário",Dados!$A$2:$A$1000,$B$3,Dados!$C$2:$C$1000,6)) | F18: =IF(COUNTIFS(Dados!$A$2:$A$1000,$B$3,Dados!$C$2:$C$1000,6)=0,"",SUMIFS(Dados!$F$2:$F$1000,Dados!$D$2:$D$1000,"Criptoativo",Dados!$A$2:$A$1000,$B$3,Dados!$C$2:$C$1000,6))
A19: Julho | B19: =IF(COUNTIFS(Dados!$A$2:$A$1000,$B$3,Dados!$C$2:$C$1000,7)=0,"",SUM(C19:F19)) -> 39808.01 | C19: =IF(COUNTIFS(Dados!$A$2:$A$1000,$B$3,Dados!$C$2:$C$1000,7)=0,"",SUMIFS(Dados!$F$2:$F$1000,Dados!$D$2:$D$1000,"Conta Principal",Dados!$A$2:$A$1000,$B$3,Dados!$C$2:$C$1000,7)) -> 3377.66 | D19: =IF(COUNTIFS(Dados!$A$2:$A$1000,$B$3,Dados!$C$2:$C$1000,7)=0,"",SUMIFS(Dados!$F$2:$F$1000,Dados!$D$2:$D$1000,"Investimento",Dados!$A$2:$A$1000,$B$3,Dados!$C$2:$C$1000,7)) -> 36399.35 | E19: =IF(COUNTIFS(Dados!$A$2:$A$1000,$B$3,Dados!$C$2:$C$1000,7)=0,"",SUMIFS(Dados!$F$2:$F$1000,Dados!$D$2:$D$1000,"Numerário",Dados!$A$2:$A$1000,$B$3,Dados!$C$2:$C$1000,7)) -> 0 | F19: =IF(COUNTIFS(Dados!$A$2:$A$1000,$B$3,Dados!$C$2:$C$1000,7)=0,"",SUMIFS(Dados!$F$2:$F$1000,Dados!$D$2:$D$1000,"Criptoativo",Dados!$A$2:$A$1000,$B$3,Dados!$C$2:$C$1000,7)) -> 31
A20: Agosto | B20: =IF(COUNTIFS(Dados!$A$2:$A$1000,$B$3,Dados!$C$2:$C$1000,8)=0,"",SUM(C20:F20)) -> 38970.51 | C20: =IF(COUNTIFS(Dados!$A$2:$A$1000,$B$3,Dados!$C$2:$C$1000,8)=0,"",SUMIFS(Dados!$F$2:$F$1000,Dados!$D$2:$D$1000,"Conta Principal",Dados!$A$2:$A$1000,$B$3,Dados!$C$2:$C$1000,8)) -> 1969.12 | D20: =IF(COUNTIFS(Dados!$A$2:$A$1000,$B$3,Dados!$C$2:$C$1000,8)=0,"",SUMIFS(Dados!$F$2:$F$1000,Dados!$D$2:$D$1000,"Investimento",Dados!$A$2:$A$1000,$B$3,Dados!$C$2:$C$1000,8)) -> 36953.39 | E20: =IF(COUNTIFS(Dados!$A$2:$A$1000,$B$3,Dados!$C$2:$C$1000,8)=0,"",SUMIFS(Dados!$F$2:$F$1000,Dados!$D$2:$D$1000,"Numerário",Dados!$A$2:$A$1000,$B$3,Dados!$C$2:$C$1000,8)) -> 10 | F20: =IF(COUNTIFS(Dados!$A$2:$A$1000,$B$3,Dados!$C$2:$C$1000,8)=0,"",SUMIFS(Dados!$F$2:$F$1000,Dados!$D$2:$D$1000,"Criptoativo",Dados!$A$2:$A$1000,$B$3,Dados!$C$2:$C$1000,8)) -> 38
A21: Setembro | B21: =IF(COUNTIFS(Dados!$A$2:$A$1000,$B$3,Dados!$C$2:$C$1000,9)=0,"",SUM(C21:F21)) | C21: =IF(COUNTIFS(Dados!$A$2:$A$1000,$B$3,Dados!$C$2:$C$1000,9)=0,"",SUMIFS(Dados!$F$2:$F$1000,Dados!$D$2:$D$1000,"Conta Principal",Dados!$A$2:$A$1000,$B$3,Dados!$C$2:$C$1000,9)) | D21: =IF(COUNTIFS(Dados!$A$2:$A$1000,$B$3,Dados!$C$2:$C$1000,9)=0,"",SUMIFS(Dados!$F$2:$F$1000,Dados!$D$2:$D$1000,"Investimento",Dados!$A$2:$A$1000,$B$3,Dados!$C$2:$C$1000,9)) | E21: =IF(COUNTIFS(Dados!$A$2:$A$1000,$B$3,Dados!$C$2:$C$1000,9)=0,"",SUMIFS(Dados!$F$2:$F$1000,Dados!$D$2:$D$1000,"Numerário",Dados!$A$2:$A$1000,$B$3,Dados!$C$2:$C$1000,9)) | F21: =IF(COUNTIFS(Dados!$A$2:$A$1000,$B$3,Dados!$C$2:$C$1000,9)=0,"",SUMIFS(Dados!$F$2:$F$1000,Dados!$D$2:$D$1000,"Criptoativo",Dados!$A$2:$A$1000,$B$3,Dados!$C$2:$C$1000,9))
A22: Outubro | B22: =IF(COUNTIFS(Dados!$A$2:$A$1000,$B$3,Dados!$C$2:$C$1000,10)=0,"",SUM(C22:F22)) | C22: =IF(COUNTIFS(Dados!$A$2:$A$1000,$B$3,Dados!$C$2:$C$1000,10)=0,"",SUMIFS(Dados!$F$2:$F$1000,Dados!$D$2:$D$1000,"Conta Principal",Dados!$A$2:$A$1000,$B$3,Dados!$C$2:$C$1000,10)) | D22: =IF(COUNTIFS(Dados!$A$2:$A$1000,$B$3,Dados!$C$2:$C$1000,10)=0,"",SUMIFS(Dados!$F$2:$F$1000,Dados!$D$2:$D$1000,"Investimento",Dados!$A$2:$A$1000,$B$3,Dados!$C$2:$C$1000,10)) | E22: =IF(COUNTIFS(Dados!$A$2:$A$1000,$B$3,Dados!$C$2:$C$1000,10)=0,"",SUMIFS(Dados!$F$2:$F$1000,Dados!$D$2:$D$1000,"Numerário",Dados!$A$2:$A$1000,$B$3,Dados!$C$2:$C$1000,10)) | F22: =IF(COUNTIFS(Dados!$A$2:$A$1000,$B$3,Dados!$C$2:$C$1000,10)=0,"",SUMIFS(Dados!$F$2:$F$1000,Dados!$D$2:$D$1000,"Criptoativo",Dados!$A$2:$A$1000,$B$3,Dados!$C$2:$C$1000,10))
A23: Novembro | B23: =IF(COUNTIFS(Dados!$A$2:$A$1000,$B$3,Dados!$C$2:$C$1000,11)=0,"",SUM(C23:F23)) | C23: =IF(COUNTIFS(Dados!$A$2:$A$1000,$B$3,Dados!$C$2:$C$1000,11)=0,"",SUMIFS(Dados!$F$2:$F$1000,Dados!$D$2:$D$1000,"Conta Principal",Dados!$A$2:$A$1000,$B$3,Dados!$C$2:$C$1000,11)) | D23: =IF(COUNTIFS(Dados!$A$2:$A$1000,$B$3,Dados!$C$2:$C$1000,11)=0,"",SUMIFS(Dados!$F$2:$F$1000,Dados!$D$2:$D$1000,"Investimento",Dados!$A$2:$A$1000,$B$3,Dados!$C$2:$C$1000,11)) | E23: =IF(COUNTIFS(Dados!$A$2:$A$1000,$B$3,Dados!$C$2:$C$1000,11)=0,"",SUMIFS(Dados!$F$2:$F$1000,Dados!$D$2:$D$1000,"Numerário",Dados!$A$2:$A$1000,$B$3,Dados!$C$2:$C$1000,11)) | F23: =IF(COUNTIFS(Dados!$A$2:$A$1000,$B$3,Dados!$C$2:$C$1000,11)=0,"",SUMIFS(Dados!$F$2:$F$1000,Dados!$D$2:$D$1000,"Criptoativo",Dados!$A$2:$A$1000,$B$3,Dados!$C$2:$C$1000,11))
A24: Dezembro | B24: =IF(COUNTIFS(Dados!$A$2:$A$1000,$B$3,Dados!$C$2:$C$1000,12)=0,"",SUM(C24:F24)) | C24: =IF(COUNTIFS(Dados!$A$2:$A$1000,$B$3,Dados!$C$2:$C$1000,12)=0,"",SUMIFS(Dados!$F$2:$F$1000,Dados!$D$2:$D$1000,"Conta Principal",Dados!$A$2:$A$1000,$B$3,Dados!$C$2:$C$1000,12)) | D24: =IF(COUNTIFS(Dados!$A$2:$A$1000,$B$3,Dados!$C$2:$C$1000,12)=0,"",SUMIFS(Dados!$F$2:$F$1000,Dados!$D$2:$D$1000,"Investimento",Dados!$A$2:$A$1000,$B$3,Dados!$C$2:$C$1000,12)) | E24: =IF(COUNTIFS(Dados!$A$2:$A$1000,$B$3,Dados!$C$2:$C$1000,12)=0,"",SUMIFS(Dados!$F$2:$F$1000,Dados!$D$2:$D$1000,"Numerário",Dados!$A$2:$A$1000,$B$3,Dados!$C$2:$C$1000,12)) | F24: =IF(COUNTIFS(Dados!$A$2:$A$1000,$B$3,Dados!$C$2:$C$1000,12)=0,"",SUMIFS(Dados!$F$2:$F$1000,Dados!$D$2:$D$1000,"Criptoativo",Dados!$A$2:$A$1000,$B$3,Dados!$C$2:$C$1000,12))
A27: Saldo por plataforma de investimento (ano corrente)
A28: Plataforma | B28: Jan | C28: Fev | D28: Mar | E28: Abr | F28: Mai | G28: Jun | H28: Jul | I28: Ago | J28: Set | K28: Out | L28: Nov | M28: Dez
A29: Activobank | B29: =IF(COUNTIFS(Dados!$A$2:$A$1000,$B$3,Dados!$C$2:$C$1000,1,Dados!$E$2:$E$1000,"Activobank")=0,"",SUMIFS(Dados!$F$2:$F$1000,Dados!$D$2:$D$1000,"Investimento",Dados!$E$2:$E$1000,"Activobank",Dados!$A$2:$A$1000,$B$3,Dados!$C$2:$C$1000,1)) -> 4000 | C29: =IF(COUNTIFS(Dados!$A$2:$A$1000,$B$3,Dados!$C$2:$C$1000,2,Dados!$E$2:$E$1000,"Activobank")=0,"",SUMIFS(Dados!$F$2:$F$1000,Dados!$D$2:$D$1000,"Investimento",Dados!$E$2:$E$1000,"Activobank",Dados!$A$2:$A$1000,$B$3,Dados!$C$2:$C$1000,2)) -> 267.71 | D29: =IF(COUNTIFS(Dados!$A$2:$A$1000,$B$3,Dados!$C$2:$C$1000,3,Dados!$E$2:$E$1000,"Activobank")=0,"",SUMIFS(Dados!$F$2:$F$1000,Dados!$D$2:$D$1000,"Investimento",Dados!$E$2:$E$1000,"Activobank",Dados!$A$2:$A$1000,$B$3,Dados!$C$2:$C$1000,3)) -> 100 | E29: =IF(COUNTIFS(Dados!$A$2:$A$1000,$B$3,Dados!$C$2:$C$1000,4,Dados!$E$2:$E$1000,"Activobank")=0,"",SUMIFS(Dados!$F$2:$F$1000,Dados!$D$2:$D$1000,"Investimento",Dados!$E$2:$E$1000,"Activobank",Dados!$A$2:$A$1000,$B$3,Dados!$C$2:$C$1000,4)) -> 100 | F29: =IF(COUNTIFS(Dados!$A$2:$A$1000,$B$3,Dados!$C$2:$C$1000,5,Dados!$E$2:$E$1000,"Activobank")=0,"",SUMIFS(Dados!$F$2:$F$1000,Dados!$D$2:$D$1000,"Investimento",Dados!$E$2:$E$1000,"Activobank",Dados!$A$2:$A$1000,$B$3,Dados!$C$2:$C$1000,5)) -> 100 | G29: =IF(COUNTIFS(Dados!$A$2:$A$1000,$B$3,Dados!$C$2:$C$1000,6,Dados!$E$2:$E$1000,"Activobank")=0,"",SUMIFS(Dados!$F$2:$F$1000,Dados!$D$2:$D$1000,"Investimento",Dados!$E$2:$E$1000,"Activobank",Dados!$A$2:$A$1000,$B$3,Dados!$C$2:$C$1000,6)) | H29: =IF(COUNTIFS(Dados!$A$2:$A$1000,$B$3,Dados!$C$2:$C$1000,7,Dados!$E$2:$E$1000,"Activobank")=0,"",SUMIFS(Dados!$F$2:$F$1000,Dados!$D$2:$D$1000,"Investimento",Dados!$E$2:$E$1000,"Activobank",Dados!$A$2:$A$1000,$B$3,Dados!$C$2:$C$1000,7)) -> 100 | I29: =IF(COUNTIFS(Dados!$A$2:$A$1000,$B$3,Dados!$C$2:$C$1000,8,Dados!$E$2:$E$1000,"Activobank")=0,"",SUMIFS(Dados!$F$2:$F$1000,Dados!$D$2:$D$1000,"Investimento",Dados!$E$2:$E$1000,"Activobank",Dados!$A$2:$A$1000,$B$3,Dados!$C$2:$C$1000,8)) -> 100 | J29: =IF(COUNTIFS(Dados!$A$2:$A$1000,$B$3,Dados!$C$2:$C$1000,9,Dados!$E$2:$E$1000,"Activobank")=0,"",SUMIFS(Dados!$F$2:$F$1000,Dados!$D$2:$D$1000,"Investimento",Dados!$E$2:$E$1000,"Activobank",Dados!$A$2:$A$1000,$B$3,Dados!$C$2:$C$1000,9)) | K29: =IF(COUNTIFS(Dados!$A$2:$A$1000,$B$3,Dados!$C$2:$C$1000,10,Dados!$E$2:$E$1000,"Activobank")=0,"",SUMIFS(Dados!$F$2:$F$1000,Dados!$D$2:$D$1000,"Investimento",Dados!$E$2:$E$1000,"Activobank",Dados!$A$2:$A$1000,$B$3,Dados!$C$2:$C$1000,10)) | L29: =IF(COUNTIFS(Dados!$A$2:$A$1000,$B$3,Dados!$C$2:$C$1000,11,Dados!$E$2:$E$1000,"Activobank")=0,"",SUMIFS(Dados!$F$2:$F$1000,Dados!$D$2:$D$1000,"Investimento",Dados!$E$2:$E$1000,"Activobank",Dados!$A$2:$A$1000,$B$3,Dados!$C$2:$C$1000,11)) | M29: =IF(COUNTIFS(Dados!$A$2:$A$1000,$B$3,Dados!$C$2:$C$1000,12,Dados!$E$2:$E$1000,"Activobank")=0,"",SUMIFS(Dados!$F$2:$F$1000,Dados!$D$2:$D$1000,"Investimento",Dados!$E$2:$E$1000,"Activobank",Dados!$A$2:$A$1000,$B$3,Dados!$C$2:$C$1000,12))
A30: Bondora Go & Grow | B30: =IF(COUNTIFS(Dados!$A$2:$A$1000,$B$3,Dados!$C$2:$C$1000,1,Dados!$E$2:$E$1000,"Bondora Go & Grow")=0,"",SUMIFS(Dados!$F$2:$F$1000,Dados!$D$2:$D$1000,"Investimento",Dados!$E$2:$E$1000,"Bondora Go & Grow",Dados!$A$2:$A$1000,$B$3,Dados!$C$2:$C$1000,1)) -> 6251.29 | C30: =IF(COUNTIFS(Dados!$A$2:$A$1000,$B$3,Dados!$C$2:$C$1000,2,Dados!$E$2:$E$1000,"Bondora Go & Grow")=0,"",SUMIFS(Dados!$F$2:$F$1000,Dados!$D$2:$D$1000,"Investimento",Dados!$E$2:$E$1000,"Bondora Go & Grow",Dados!$A$2:$A$1000,$B$3,Dados!$C$2:$C$1000,2)) -> 6309.34 | D30: =IF(COUNTIFS(Dados!$A$2:$A$1000,$B$3,Dados!$C$2:$C$1000,3,Dados!$E$2:$E$1000,"Bondora Go & Grow")=0,"",SUMIFS(Dados!$F$2:$F$1000,Dados!$D$2:$D$1000,"Investimento",Dados!$E$2:$E$1000,"Bondora Go & Grow",Dados!$A$2:$A$1000,$B$3,Dados!$C$2:$C$1000,3)) -> 6386.73 | E30: =IF(COUNTIFS(Dados!$A$2:$A$1000,$B$3,Dados!$C$2:$C$1000,4,Dados!$E$2:$E$1000,"Bondora Go & Grow")=0,"",SUMIFS(Dados!$F$2:$F$1000,Dados!$D$2:$D$1000,"Investimento",Dados!$E$2:$E$1000,"Bondora Go & Grow",Dados!$A$2:$A$1000,$B$3,Dados!$C$2:$C$1000,4)) -> 6479.54 | F30: =IF(COUNTIFS(Dados!$A$2:$A$1000,$B$3,Dados!$C$2:$C$1000,5,Dados!$E$2:$E$1000,"Bondora Go & Grow")=0,"",SUMIFS(Dados!$F$2:$F$1000,Dados!$D$2:$D$1000,"Investimento",Dados!$E$2:$E$1000,"Bondora Go & Grow",Dados!$A$2:$A$1000,$B$3,Dados!$C$2:$C$1000,5)) -> 6611.92 | G30: =IF(COUNTIFS(Dados!$A$2:$A$1000,$B$3,Dados!$C$2:$C$1000,6,Dados!$E$2:$E$1000,"Bondora Go & Grow")=0,"",SUMIFS(Dados!$F$2:$F$1000,Dados!$D$2:$D$1000,"Investimento",Dados!$E$2:$E$1000,"Bondora Go & Grow",Dados!$A$2:$A$1000,$B$3,Dados!$C$2:$C$1000,6)) | H30: =IF(COUNTIFS(Dados!$A$2:$A$1000,$B$3,Dados!$C$2:$C$1000,7,Dados!$E$2:$E$1000,"Bondora Go & Grow")=0,"",SUMIFS(Dados!$F$2:$F$1000,Dados!$D$2:$D$1000,"Investimento",Dados!$E$2:$E$1000,"Bondora Go & Grow",Dados!$A$2:$A$1000,$B$3,Dados!$C$2:$C$1000,7)) -> 6889.6 | I30: =IF(COUNTIFS(Dados!$A$2:$A$1000,$B$3,Dados!$C$2:$C$1000,8,Dados!$E$2:$E$1000,"Bondora Go & Grow")=0,"",SUMIFS(Dados!$F$2:$F$1000,Dados!$D$2:$D$1000,"Investimento",Dados!$E$2:$E$1000,"Bondora Go & Grow",Dados!$A$2:$A$1000,$B$3,Dados!$C$2:$C$1000,8)) -> 7089.2 | J30: =IF(COUNTIFS(Dados!$A$2:$A$1000,$B$3,Dados!$C$2:$C$1000,9,Dados!$E$2:$E$1000,"Bondora Go & Grow")=0,"",SUMIFS(Dados!$F$2:$F$1000,Dados!$D$2:$D$1000,"Investimento",Dados!$E$2:$E$1000,"Bondora Go & Grow",Dados!$A$2:$A$1000,$B$3,Dados!$C$2:$C$1000,9)) | K30: =IF(COUNTIFS(Dados!$A$2:$A$1000,$B$3,Dados!$C$2:$C$1000,10,Dados!$E$2:$E$1000,"Bondora Go & Grow")=0,"",SUMIFS(Dados!$F$2:$F$1000,Dados!$D$2:$D$1000,"Investimento",Dados!$E$2:$E$1000,"Bondora Go & Grow",Dados!$A$2:$A$1000,$B$3,Dados!$C$2:$C$1000,10)) | L30: =IF(COUNTIFS(Dados!$A$2:$A$1000,$B$3,Dados!$C$2:$C$1000,11,Dados!$E$2:$E$1000,"Bondora Go & Grow")=0,"",SUMIFS(Dados!$F$2:$F$1000,Dados!$D$2:$D$1000,"Investimento",Dados!$E$2:$E$1000,"Bondora Go & Grow",Dados!$A$2:$A$1000,$B$3,Dados!$C$2:$C$1000,11)) | M30: =IF(COUNTIFS(Dados!$A$2:$A$1000,$B$3,Dados!$C$2:$C$1000,12,Dados!$E$2:$E$1000,"Bondora Go & Grow")=0,"",SUMIFS(Dados!$F$2:$F$1000,Dados!$D$2:$D$1000,"Investimento",Dados!$E$2:$E$1000,"Bondora Go & Grow",Dados!$A$2:$A$1000,$B$3,Dados!$C$2:$C$1000,12))
A31: Degiro | B31: =IF(COUNTIFS(Dados!$A$2:$A$1000,$B$3,Dados!$C$2:$C$1000,1,Dados!$E$2:$E$1000,"Degiro")=0,"",SUMIFS(Dados!$F$2:$F$1000,Dados!$D$2:$D$1000,"Investimento",Dados!$E$2:$E$1000,"Degiro",Dados!$A$2:$A$1000,$B$3,Dados!$C$2:$C$1000,1)) -> 2010.83 | C31: =IF(COUNTIFS(Dados!$A$2:$A$1000,$B$3,Dados!$C$2:$C$1000,2,Dados!$E$2:$E$1000,"Degiro")=0,"",SUMIFS(Dados!$F$2:$F$1000,Dados!$D$2:$D$1000,"Investimento",Dados!$E$2:$E$1000,"Degiro",Dados!$A$2:$A$1000,$B$3,Dados!$C$2:$C$1000,2)) -> 2046.34 | D31: =IF(COUNTIFS(Dados!$A$2:$A$1000,$B$3,Dados!$C$2:$C$1000,3,Dados!$E$2:$E$1000,"Degiro")=0,"",SUMIFS(Dados!$F$2:$F$1000,Dados!$D$2:$D$1000,"Investimento",Dados!$E$2:$E$1000,"Degiro",Dados!$A$2:$A$1000,$B$3,Dados!$C$2:$C$1000,3)) -> 1971.27 | E31: =IF(COUNTIFS(Dados!$A$2:$A$1000,$B$3,Dados!$C$2:$C$1000,4,Dados!$E$2:$E$1000,"Degiro")=0,"",SUMIFS(Dados!$F$2:$F$1000,Dados!$D$2:$D$1000,"Investimento",Dados!$E$2:$E$1000,"Degiro",Dados!$A$2:$A$1000,$B$3,Dados!$C$2:$C$1000,4)) -> 2189.55 | F31: =IF(COUNTIFS(Dados!$A$2:$A$1000,$B$3,Dados!$C$2:$C$1000,5,Dados!$E$2:$E$1000,"Degiro")=0,"",SUMIFS(Dados!$F$2:$F$1000,Dados!$D$2:$D$1000,"Investimento",Dados!$E$2:$E$1000,"Degiro",Dados!$A$2:$A$1000,$B$3,Dados!$C$2:$C$1000,5)) -> 2274 | G31: =IF(COUNTIFS(Dados!$A$2:$A$1000,$B$3,Dados!$C$2:$C$1000,6,Dados!$E$2:$E$1000,"Degiro")=0,"",SUMIFS(Dados!$F$2:$F$1000,Dados!$D$2:$D$1000,"Investimento",Dados!$E$2:$E$1000,"Degiro",Dados!$A$2:$A$1000,$B$3,Dados!$C$2:$C$1000,6)) | H31: =IF(COUNTIFS(Dados!$A$2:$A$1000,$B$3,Dados!$C$2:$C$1000,7,Dados!$E$2:$E$1000,"Degiro")=0,"",SUMIFS(Dados!$F$2:$F$1000,Dados!$D$2:$D$1000,"Investimento",Dados!$E$2:$E$1000,"Degiro",Dados!$A$2:$A$1000,$B$3,Dados!$C$2:$C$1000,7)) -> 2334.07 | I31: =IF(COUNTIFS(Dados!$A$2:$A$1000,$B$3,Dados!$C$2:$C$1000,8,Dados!$E$2:$E$1000,"Degiro")=0,"",SUMIFS(Dados!$F$2:$F$1000,Dados!$D$2:$D$1000,"Investimento",Dados!$E$2:$E$1000,"Degiro",Dados!$A$2:$A$1000,$B$3,Dados!$C$2:$C$1000,8)) -> 2430.88 | J31: =IF(COUNTIFS(Dados!$A$2:$A$1000,$B$3,Dados!$C$2:$C$1000,9,Dados!$E$2:$E$1000,"Degiro")=0,"",SUMIFS(Dados!$F$2:$F$1000,Dados!$D$2:$D$1000,"Investimento",Dados!$E$2:$E$1000,"Degiro",Dados!$A$2:$A$1000,$B$3,Dados!$C$2:$C$1000,9)) | K31: =IF(COUNTIFS(Dados!$A$2:$A$1000,$B$3,Dados!$C$2:$C$1000,10,Dados!$E$2:$E$1000,"Degiro")=0,"",SUMIFS(Dados!$F$2:$F$1000,Dados!$D$2:$D$1000,"Investimento",Dados!$E$2:$E$1000,"Degiro",Dados!$A$2:$A$1000,$B$3,Dados!$C$2:$C$1000,10)) | L31: =IF(COUNTIFS(Dados!$A$2:$A$1000,$B$3,Dados!$C$2:$C$1000,11,Dados!$E$2:$E$1000,"Degiro")=0,"",SUMIFS(Dados!$F$2:$F$1000,Dados!$D$2:$D$1000,"Investimento",Dados!$E$2:$E$1000,"Degiro",Dados!$A$2:$A$1000,$B$3,Dados!$C$2:$C$1000,11)) | M31: =IF(COUNTIFS(Dados!$A$2:$A$1000,$B$3,Dados!$C$2:$C$1000,12,Dados!$E$2:$E$1000,"Degiro")=0,"",SUMIFS(Dados!$F$2:$F$1000,Dados!$D$2:$D$1000,"Investimento",Dados!$E$2:$E$1000,"Degiro",Dados!$A$2:$A$1000,$B$3,Dados!$C$2:$C$1000,12))
A32: Golden SGF | B32: =IF(COUNTIFS(Dados!$A$2:$A$1000,$B$3,Dados!$C$2:$C$1000,1,Dados!$E$2:$E$1000,"Golden SGF")=0,"",SUMIFS(Dados!$F$2:$F$1000,Dados!$D$2:$D$1000,"Investimento",Dados!$E$2:$E$1000,"Golden SGF",Dados!$A$2:$A$1000,$B$3,Dados!$C$2:$C$1000,1)) -> 2503.69 | C32: =IF(COUNTIFS(Dados!$A$2:$A$1000,$B$3,Dados!$C$2:$C$1000,2,Dados!$E$2:$E$1000,"Golden SGF")=0,"",SUMIFS(Dados!$F$2:$F$1000,Dados!$D$2:$D$1000,"Investimento",Dados!$E$2:$E$1000,"Golden SGF",Dados!$A$2:$A$1000,$B$3,Dados!$C$2:$C$1000,2)) -> 2557.77 | D32: =IF(COUNTIFS(Dados!$A$2:$A$1000,$B$3,Dados!$C$2:$C$1000,3,Dados!$E$2:$E$1000,"Golden SGF")=0,"",SUMIFS(Dados!$F$2:$F$1000,Dados!$D$2:$D$1000,"Investimento",Dados!$E$2:$E$1000,"Golden SGF",Dados!$A$2:$A$1000,$B$3,Dados!$C$2:$C$1000,3)) -> 2504.71 | E32: =IF(COUNTIFS(Dados!$A$2:$A$1000,$B$3,Dados!$C$2:$C$1000,4,Dados!$E$2:$E$1000,"Golden SGF")=0,"",SUMIFS(Dados!$F$2:$F$1000,Dados!$D$2:$D$1000,"Investimento",Dados!$E$2:$E$1000,"Golden SGF",Dados!$A$2:$A$1000,$B$3,Dados!$C$2:$C$1000,4)) -> 2659.51 | F32: =IF(COUNTIFS(Dados!$A$2:$A$1000,$B$3,Dados!$C$2:$C$1000,5,Dados!$E$2:$E$1000,"Golden SGF")=0,"",SUMIFS(Dados!$F$2:$F$1000,Dados!$D$2:$D$1000,"Investimento",Dados!$E$2:$E$1000,"Golden SGF",Dados!$A$2:$A$1000,$B$3,Dados!$C$2:$C$1000,5)) -> 2778.22 | G32: =IF(COUNTIFS(Dados!$A$2:$A$1000,$B$3,Dados!$C$2:$C$1000,6,Dados!$E$2:$E$1000,"Golden SGF")=0,"",SUMIFS(Dados!$F$2:$F$1000,Dados!$D$2:$D$1000,"Investimento",Dados!$E$2:$E$1000,"Golden SGF",Dados!$A$2:$A$1000,$B$3,Dados!$C$2:$C$1000,6)) | H32: =IF(COUNTIFS(Dados!$A$2:$A$1000,$B$3,Dados!$C$2:$C$1000,7,Dados!$E$2:$E$1000,"Golden SGF")=0,"",SUMIFS(Dados!$F$2:$F$1000,Dados!$D$2:$D$1000,"Investimento",Dados!$E$2:$E$1000,"Golden SGF",Dados!$A$2:$A$1000,$B$3,Dados!$C$2:$C$1000,7)) -> 2884.95 | I32: =IF(COUNTIFS(Dados!$A$2:$A$1000,$B$3,Dados!$C$2:$C$1000,8,Dados!$E$2:$E$1000,"Golden SGF")=0,"",SUMIFS(Dados!$F$2:$F$1000,Dados!$D$2:$D$1000,"Investimento",Dados!$E$2:$E$1000,"Golden SGF",Dados!$A$2:$A$1000,$B$3,Dados!$C$2:$C$1000,8)) -> 2991.1 | J32: =IF(COUNTIFS(Dados!$A$2:$A$1000,$B$3,Dados!$C$2:$C$1000,9,Dados!$E$2:$E$1000,"Golden SGF")=0,"",SUMIFS(Dados!$F$2:$F$1000,Dados!$D$2:$D$1000,"Investimento",Dados!$E$2:$E$1000,"Golden SGF",Dados!$A$2:$A$1000,$B$3,Dados!$C$2:$C$1000,9)) | K32: =IF(COUNTIFS(Dados!$A$2:$A$1000,$B$3,Dados!$C$2:$C$1000,10,Dados!$E$2:$E$1000,"Golden SGF")=0,"",SUMIFS(Dados!$F$2:$F$1000,Dados!$D$2:$D$1000,"Investimento",Dados!$E$2:$E$1000,"Golden SGF",Dados!$A$2:$A$1000,$B$3,Dados!$C$2:$C$1000,10)) | L32: =IF(COUNTIFS(Dados!$A$2:$A$1000,$B$3,Dados!$C$2:$C$1000,11,Dados!$E$2:$E$1000,"Golden SGF")=0,"",SUMIFS(Dados!$F$2:$F$1000,Dados!$D$2:$D$1000,"Investimento",Dados!$E$2:$E$1000,"Golden SGF",Dados!$A$2:$A$1000,$B$3,Dados!$C$2:$C$1000,11)) | M32: =IF(COUNTIFS(Dados!$A$2:$A$1000,$B$3,Dados!$C$2:$C$1000,12,Dados!$E$2:$E$1000,"Golden SGF")=0,"",SUMIFS(Dados!$F$2:$F$1000,Dados!$D$2:$D$1000,"Investimento",Dados!$E$2:$E$1000,"Golden SGF",Dados!$A$2:$A$1000,$B$3,Dados!$C$2:$C$1000,12))
A33: IGCP | B33: =IF(COUNTIFS(Dados!$A$2:$A$1000,$B$3,Dados!$C$2:$C$1000,1,Dados!$E$2:$E$1000,"IGCP")=0,"",SUMIFS(Dados!$F$2:$F$1000,Dados!$D$2:$D$1000,"Investimento",Dados!$E$2:$E$1000,"IGCP",Dados!$A$2:$A$1000,$B$3,Dados!$C$2:$C$1000,1)) -> 2707.43 | C33: =IF(COUNTIFS(Dados!$A$2:$A$1000,$B$3,Dados!$C$2:$C$1000,2,Dados!$E$2:$E$1000,"IGCP")=0,"",SUMIFS(Dados!$F$2:$F$1000,Dados!$D$2:$D$1000,"Investimento",Dados!$E$2:$E$1000,"IGCP",Dados!$A$2:$A$1000,$B$3,Dados!$C$2:$C$1000,2)) -> 2707.43 | D33: =IF(COUNTIFS(Dados!$A$2:$A$1000,$B$3,Dados!$C$2:$C$1000,3,Dados!$E$2:$E$1000,"IGCP")=0,"",SUMIFS(Dados!$F$2:$F$1000,Dados!$D$2:$D$1000,"Investimento",Dados!$E$2:$E$1000,"IGCP",Dados!$A$2:$A$1000,$B$3,Dados!$C$2:$C$1000,3)) -> 2707.43 | E33: =IF(COUNTIFS(Dados!$A$2:$A$1000,$B$3,Dados!$C$2:$C$1000,4,Dados!$E$2:$E$1000,"IGCP")=0,"",SUMIFS(Dados!$F$2:$F$1000,Dados!$D$2:$D$1000,"Investimento",Dados!$E$2:$E$1000,"IGCP",Dados!$A$2:$A$1000,$B$3,Dados!$C$2:$C$1000,4)) -> 2724.75 | F33: =IF(COUNTIFS(Dados!$A$2:$A$1000,$B$3,Dados!$C$2:$C$1000,5,Dados!$E$2:$E$1000,"IGCP")=0,"",SUMIFS(Dados!$F$2:$F$1000,Dados!$D$2:$D$1000,"Investimento",Dados!$E$2:$E$1000,"IGCP",Dados!$A$2:$A$1000,$B$3,Dados!$C$2:$C$1000,5)) -> 2724.75 | G33: =IF(COUNTIFS(Dados!$A$2:$A$1000,$B$3,Dados!$C$2:$C$1000,6,Dados!$E$2:$E$1000,"IGCP")=0,"",SUMIFS(Dados!$F$2:$F$1000,Dados!$D$2:$D$1000,"Investimento",Dados!$E$2:$E$1000,"IGCP",Dados!$A$2:$A$1000,$B$3,Dados!$C$2:$C$1000,6)) | H33: =IF(COUNTIFS(Dados!$A$2:$A$1000,$B$3,Dados!$C$2:$C$1000,7,Dados!$E$2:$E$1000,"IGCP")=0,"",SUMIFS(Dados!$F$2:$F$1000,Dados!$D$2:$D$1000,"Investimento",Dados!$E$2:$E$1000,"IGCP",Dados!$A$2:$A$1000,$B$3,Dados!$C$2:$C$1000,7)) -> 2741.98 | I33: =IF(COUNTIFS(Dados!$A$2:$A$1000,$B$3,Dados!$C$2:$C$1000,8,Dados!$E$2:$E$1000,"IGCP")=0,"",SUMIFS(Dados!$F$2:$F$1000,Dados!$D$2:$D$1000,"Investimento",Dados!$E$2:$E$1000,"IGCP",Dados!$A$2:$A$1000,$B$3,Dados!$C$2:$C$1000,8)) -> 2741.98 | J33: =IF(COUNTIFS(Dados!$A$2:$A$1000,$B$3,Dados!$C$2:$C$1000,9,Dados!$E$2:$E$1000,"IGCP")=0,"",SUMIFS(Dados!$F$2:$F$1000,Dados!$D$2:$D$1000,"Investimento",Dados!$E$2:$E$1000,"IGCP",Dados!$A$2:$A$1000,$B$3,Dados!$C$2:$C$1000,9)) | K33: =IF(COUNTIFS(Dados!$A$2:$A$1000,$B$3,Dados!$C$2:$C$1000,10,Dados!$E$2:$E$1000,"IGCP")=0,"",SUMIFS(Dados!$F$2:$F$1000,Dados!$D$2:$D$1000,"Investimento",Dados!$E$2:$E$1000,"IGCP",Dados!$A$2:$A$1000,$B$3,Dados!$C$2:$C$1000,10)) | L33: =IF(COUNTIFS(Dados!$A$2:$A$1000,$B$3,Dados!$C$2:$C$1000,11,Dados!$E$2:$E$1000,"IGCP")=0,"",SUMIFS(Dados!$F$2:$F$1000,Dados!$D$2:$D$1000,"Investimento",Dados!$E$2:$E$1000,"IGCP",Dados!$A$2:$A$1000,$B$3,Dados!$C$2:$C$1000,11)) | M33: =IF(COUNTIFS(Dados!$A$2:$A$1000,$B$3,Dados!$C$2:$C$1000,12,Dados!$E$2:$E$1000,"IGCP")=0,"",SUMIFS(Dados!$F$2:$F$1000,Dados!$D$2:$D$1000,"Investimento",Dados!$E$2:$E$1000,"IGCP",Dados!$A$2:$A$1000,$B$3,Dados!$C$2:$C$1000,12))
A34: PPR Santander | B34: =IF(COUNTIFS(Dados!$A$2:$A$1000,$B$3,Dados!$C$2:$C$1000,1,Dados!$E$2:$E$1000,"PPR Santander")=0,"",SUMIFS(Dados!$F$2:$F$1000,Dados!$D$2:$D$1000,"Investimento",Dados!$E$2:$E$1000,"PPR Santander",Dados!$A$2:$A$1000,$B$3,Dados!$C$2:$C$1000,1)) -> 1709.21 | C34: =IF(COUNTIFS(Dados!$A$2:$A$1000,$B$3,Dados!$C$2:$C$1000,2,Dados!$E$2:$E$1000,"PPR Santander")=0,"",SUMIFS(Dados!$F$2:$F$1000,Dados!$D$2:$D$1000,"Investimento",Dados!$E$2:$E$1000,"PPR Santander",Dados!$A$2:$A$1000,$B$3,Dados!$C$2:$C$1000,2)) -> 1766 | D34: =IF(COUNTIFS(Dados!$A$2:$A$1000,$B$3,Dados!$C$2:$C$1000,3,Dados!$E$2:$E$1000,"PPR Santander")=0,"",SUMIFS(Dados!$F$2:$F$1000,Dados!$D$2:$D$1000,"Investimento",Dados!$E$2:$E$1000,"PPR Santander",Dados!$A$2:$A$1000,$B$3,Dados!$C$2:$C$1000,3)) -> 1784.76 | E34: =IF(COUNTIFS(Dados!$A$2:$A$1000,$B$3,Dados!$C$2:$C$1000,4,Dados!$E$2:$E$1000,"PPR Santander")=0,"",SUMIFS(Dados!$F$2:$F$1000,Dados!$D$2:$D$1000,"Investimento",Dados!$E$2:$E$1000,"PPR Santander",Dados!$A$2:$A$1000,$B$3,Dados!$C$2:$C$1000,4)) -> 1846.5 | F34: =IF(COUNTIFS(Dados!$A$2:$A$1000,$B$3,Dados!$C$2:$C$1000,5,Dados!$E$2:$E$1000,"PPR Santander")=0,"",SUMIFS(Dados!$F$2:$F$1000,Dados!$D$2:$D$1000,"Investimento",Dados!$E$2:$E$1000,"PPR Santander",Dados!$A$2:$A$1000,$B$3,Dados!$C$2:$C$1000,5)) -> 1909.28 | G34: =IF(COUNTIFS(Dados!$A$2:$A$1000,$B$3,Dados!$C$2:$C$1000,6,Dados!$E$2:$E$1000,"PPR Santander")=0,"",SUMIFS(Dados!$F$2:$F$1000,Dados!$D$2:$D$1000,"Investimento",Dados!$E$2:$E$1000,"PPR Santander",Dados!$A$2:$A$1000,$B$3,Dados!$C$2:$C$1000,6)) | H34: =IF(COUNTIFS(Dados!$A$2:$A$1000,$B$3,Dados!$C$2:$C$1000,7,Dados!$E$2:$E$1000,"PPR Santander")=0,"",SUMIFS(Dados!$F$2:$F$1000,Dados!$D$2:$D$1000,"Investimento",Dados!$E$2:$E$1000,"PPR Santander",Dados!$A$2:$A$1000,$B$3,Dados!$C$2:$C$1000,7)) -> 2001.54 | I34: =IF(COUNTIFS(Dados!$A$2:$A$1000,$B$3,Dados!$C$2:$C$1000,8,Dados!$E$2:$E$1000,"PPR Santander")=0,"",SUMIFS(Dados!$F$2:$F$1000,Dados!$D$2:$D$1000,"Investimento",Dados!$E$2:$E$1000,"PPR Santander",Dados!$A$2:$A$1000,$B$3,Dados!$C$2:$C$1000,8)) -> 2048.85 | J34: =IF(COUNTIFS(Dados!$A$2:$A$1000,$B$3,Dados!$C$2:$C$1000,9,Dados!$E$2:$E$1000,"PPR Santander")=0,"",SUMIFS(Dados!$F$2:$F$1000,Dados!$D$2:$D$1000,"Investimento",Dados!$E$2:$E$1000,"PPR Santander",Dados!$A$2:$A$1000,$B$3,Dados!$C$2:$C$1000,9)) | K34: =IF(COUNTIFS(Dados!$A$2:$A$1000,$B$3,Dados!$C$2:$C$1000,10,Dados!$E$2:$E$1000,"PPR Santander")=0,"",SUMIFS(Dados!$F$2:$F$1000,Dados!$D$2:$D$1000,"Investimento",Dados!$E$2:$E$1000,"PPR Santander",Dados!$A$2:$A$1000,$B$3,Dados!$C$2:$C$1000,10)) | L34: =IF(COUNTIFS(Dados!$A$2:$A$1000,$B$3,Dados!$C$2:$C$1000,11,Dados!$E$2:$E$1000,"PPR Santander")=0,"",SUMIFS(Dados!$F$2:$F$1000,Dados!$D$2:$D$1000,"Investimento",Dados!$E$2:$E$1000,"PPR Santander",Dados!$A$2:$A$1000,$B$3,Dados!$C$2:$C$1000,11)) | M34: =IF(COUNTIFS(Dados!$A$2:$A$1000,$B$3,Dados!$C$2:$C$1000,12,Dados!$E$2:$E$1000,"PPR Santander")=0,"",SUMIFS(Dados!$F$2:$F$1000,Dados!$D$2:$D$1000,"Investimento",Dados!$E$2:$E$1000,"PPR Santander",Dados!$A$2:$A$1000,$B$3,Dados!$C$2:$C$1000,12))
A35: Revolut | B35: =IF(COUNTIFS(Dados!$A$2:$A$1000,$B$3,Dados!$C$2:$C$1000,1,Dados!$E$2:$E$1000,"Revolut")=0,"",SUMIFS(Dados!$F$2:$F$1000,Dados!$D$2:$D$1000,"Investimento",Dados!$E$2:$E$1000,"Revolut",Dados!$A$2:$A$1000,$B$3,Dados!$C$2:$C$1000,1)) -> 226.13 | C35: =IF(COUNTIFS(Dados!$A$2:$A$1000,$B$3,Dados!$C$2:$C$1000,2,Dados!$E$2:$E$1000,"Revolut")=0,"",SUMIFS(Dados!$F$2:$F$1000,Dados!$D$2:$D$1000,"Investimento",Dados!$E$2:$E$1000,"Revolut",Dados!$A$2:$A$1000,$B$3,Dados!$C$2:$C$1000,2)) -> 246.28 | D35: =IF(COUNTIFS(Dados!$A$2:$A$1000,$B$3,Dados!$C$2:$C$1000,3,Dados!$E$2:$E$1000,"Revolut")=0,"",SUMIFS(Dados!$F$2:$F$1000,Dados!$D$2:$D$1000,"Investimento",Dados!$E$2:$E$1000,"Revolut",Dados!$A$2:$A$1000,$B$3,Dados!$C$2:$C$1000,3)) -> 266.57 | E35: =IF(COUNTIFS(Dados!$A$2:$A$1000,$B$3,Dados!$C$2:$C$1000,4,Dados!$E$2:$E$1000,"Revolut")=0,"",SUMIFS(Dados!$F$2:$F$1000,Dados!$D$2:$D$1000,"Investimento",Dados!$E$2:$E$1000,"Revolut",Dados!$A$2:$A$1000,$B$3,Dados!$C$2:$C$1000,4)) -> 287 | F35: =IF(COUNTIFS(Dados!$A$2:$A$1000,$B$3,Dados!$C$2:$C$1000,5,Dados!$E$2:$E$1000,"Revolut")=0,"",SUMIFS(Dados!$F$2:$F$1000,Dados!$D$2:$D$1000,"Investimento",Dados!$E$2:$E$1000,"Revolut",Dados!$A$2:$A$1000,$B$3,Dados!$C$2:$C$1000,5)) -> 312 | G35: =IF(COUNTIFS(Dados!$A$2:$A$1000,$B$3,Dados!$C$2:$C$1000,6,Dados!$E$2:$E$1000,"Revolut")=0,"",SUMIFS(Dados!$F$2:$F$1000,Dados!$D$2:$D$1000,"Investimento",Dados!$E$2:$E$1000,"Revolut",Dados!$A$2:$A$1000,$B$3,Dados!$C$2:$C$1000,6)) | H35: =IF(COUNTIFS(Dados!$A$2:$A$1000,$B$3,Dados!$C$2:$C$1000,7,Dados!$E$2:$E$1000,"Revolut")=0,"",SUMIFS(Dados!$F$2:$F$1000,Dados!$D$2:$D$1000,"Investimento",Dados!$E$2:$E$1000,"Revolut",Dados!$A$2:$A$1000,$B$3,Dados!$C$2:$C$1000,7)) -> 353.18 | I35: =IF(COUNTIFS(Dados!$A$2:$A$1000,$B$3,Dados!$C$2:$C$1000,8,Dados!$E$2:$E$1000,"Revolut")=0,"",SUMIFS(Dados!$F$2:$F$1000,Dados!$D$2:$D$1000,"Investimento",Dados!$E$2:$E$1000,"Revolut",Dados!$A$2:$A$1000,$B$3,Dados!$C$2:$C$1000,8)) -> 373.46 | J35: =IF(COUNTIFS(Dados!$A$2:$A$1000,$B$3,Dados!$C$2:$C$1000,9,Dados!$E$2:$E$1000,"Revolut")=0,"",SUMIFS(Dados!$F$2:$F$1000,Dados!$D$2:$D$1000,"Investimento",Dados!$E$2:$E$1000,"Revolut",Dados!$A$2:$A$1000,$B$3,Dados!$C$2:$C$1000,9)) | K35: =IF(COUNTIFS(Dados!$A$2:$A$1000,$B$3,Dados!$C$2:$C$1000,10,Dados!$E$2:$E$1000,"Revolut")=0,"",SUMIFS(Dados!$F$2:$F$1000,Dados!$D$2:$D$1000,"Investimento",Dados!$E$2:$E$1000,"Revolut",Dados!$A$2:$A$1000,$B$3,Dados!$C$2:$C$1000,10)) | L35: =IF(COUNTIFS(Dados!$A$2:$A$1000,$B$3,Dados!$C$2:$C$1000,11,Dados!$E$2:$E$1000,"Revolut")=0,"",SUMIFS(Dados!$F$2:$F$1000,Dados!$D$2:$D$1000,"Investimento",Dados!$E$2:$E$1000,"Revolut",Dados!$A$2:$A$1000,$B$3,Dados!$C$2:$C$1000,11)) | M35: =IF(COUNTIFS(Dados!$A$2:$A$1000,$B$3,Dados!$C$2:$C$1000,12,Dados!$E$2:$E$1000,"Revolut")=0,"",SUMIFS(Dados!$F$2:$F$1000,Dados!$D$2:$D$1000,"Investimento",Dados!$E$2:$E$1000,"Revolut",Dados!$A$2:$A$1000,$B$3,Dados!$C$2:$C$1000,12))
A36: Trade Republic | B36: =IF(COUNTIFS(Dados!$A$2:$A$1000,$B$3,Dados!$C$2:$C$1000,1,Dados!$E$2:$E$1000,"Trade Republic")=0,"",SUMIFS(Dados!$F$2:$F$1000,Dados!$D$2:$D$1000,"Investimento",Dados!$E$2:$E$1000,"Trade Republic",Dados!$A$2:$A$1000,$B$3,Dados!$C$2:$C$1000,1)) -> 18991.73 | C36: =IF(COUNTIFS(Dados!$A$2:$A$1000,$B$3,Dados!$C$2:$C$1000,2,Dados!$E$2:$E$1000,"Trade Republic")=0,"",SUMIFS(Dados!$F$2:$F$1000,Dados!$D$2:$D$1000,"Investimento",Dados!$E$2:$E$1000,"Trade Republic",Dados!$A$2:$A$1000,$B$3,Dados!$C$2:$C$1000,2)) -> 18991.73 | D36: =IF(COUNTIFS(Dados!$A$2:$A$1000,$B$3,Dados!$C$2:$C$1000,3,Dados!$E$2:$E$1000,"Trade Republic")=0,"",SUMIFS(Dados!$F$2:$F$1000,Dados!$D$2:$D$1000,"Investimento",Dados!$E$2:$E$1000,"Trade Republic",Dados!$A$2:$A$1000,$B$3,Dados!$C$2:$C$1000,3)) -> 17053.07 | E36: =IF(COUNTIFS(Dados!$A$2:$A$1000,$B$3,Dados!$C$2:$C$1000,4,Dados!$E$2:$E$1000,"Trade Republic")=0,"",SUMIFS(Dados!$F$2:$F$1000,Dados!$D$2:$D$1000,"Investimento",Dados!$E$2:$E$1000,"Trade Republic",Dados!$A$2:$A$1000,$B$3,Dados!$C$2:$C$1000,4)) -> 18081.26 | F36: =IF(COUNTIFS(Dados!$A$2:$A$1000,$B$3,Dados!$C$2:$C$1000,5,Dados!$E$2:$E$1000,"Trade Republic")=0,"",SUMIFS(Dados!$F$2:$F$1000,Dados!$D$2:$D$1000,"Investimento",Dados!$E$2:$E$1000,"Trade Republic",Dados!$A$2:$A$1000,$B$3,Dados!$C$2:$C$1000,5)) -> 19112.77 | G36: =IF(COUNTIFS(Dados!$A$2:$A$1000,$B$3,Dados!$C$2:$C$1000,6,Dados!$E$2:$E$1000,"Trade Republic")=0,"",SUMIFS(Dados!$F$2:$F$1000,Dados!$D$2:$D$1000,"Investimento",Dados!$E$2:$E$1000,"Trade Republic",Dados!$A$2:$A$1000,$B$3,Dados!$C$2:$C$1000,6)) | H36: =IF(COUNTIFS(Dados!$A$2:$A$1000,$B$3,Dados!$C$2:$C$1000,7,Dados!$E$2:$E$1000,"Trade Republic")=0,"",SUMIFS(Dados!$F$2:$F$1000,Dados!$D$2:$D$1000,"Investimento",Dados!$E$2:$E$1000,"Trade Republic",Dados!$A$2:$A$1000,$B$3,Dados!$C$2:$C$1000,7)) -> 18671.83 | I36: =IF(COUNTIFS(Dados!$A$2:$A$1000,$B$3,Dados!$C$2:$C$1000,8,Dados!$E$2:$E$1000,"Trade Republic")=0,"",SUMIFS(Dados!$F$2:$F$1000,Dados!$D$2:$D$1000,"Investimento",Dados!$E$2:$E$1000,"Trade Republic",Dados!$A$2:$A$1000,$B$3,Dados!$C$2:$C$1000,8)) -> 18697.52 | J36: =IF(COUNTIFS(Dados!$A$2:$A$1000,$B$3,Dados!$C$2:$C$1000,9,Dados!$E$2:$E$1000,"Trade Republic")=0,"",SUMIFS(Dados!$F$2:$F$1000,Dados!$D$2:$D$1000,"Investimento",Dados!$E$2:$E$1000,"Trade Republic",Dados!$A$2:$A$1000,$B$3,Dados!$C$2:$C$1000,9)) | K36: =IF(COUNTIFS(Dados!$A$2:$A$1000,$B$3,Dados!$C$2:$C$1000,10,Dados!$E$2:$E$1000,"Trade Republic")=0,"",SUMIFS(Dados!$F$2:$F$1000,Dados!$D$2:$D$1000,"Investimento",Dados!$E$2:$E$1000,"Trade Republic",Dados!$A$2:$A$1000,$B$3,Dados!$C$2:$C$1000,10)) | L36: =IF(COUNTIFS(Dados!$A$2:$A$1000,$B$3,Dados!$C$2:$C$1000,11,Dados!$E$2:$E$1000,"Trade Republic")=0,"",SUMIFS(Dados!$F$2:$F$1000,Dados!$D$2:$D$1000,"Investimento",Dados!$E$2:$E$1000,"Trade Republic",Dados!$A$2:$A$1000,$B$3,Dados!$C$2:$C$1000,11)) | M36: =IF(COUNTIFS(Dados!$A$2:$A$1000,$B$3,Dados!$C$2:$C$1000,12,Dados!$E$2:$E$1000,"Trade Republic")=0,"",SUMIFS(Dados!$F$2:$F$1000,Dados!$D$2:$D$1000,"Investimento",Dados!$E$2:$E$1000,"Trade Republic",Dados!$A$2:$A$1000,$B$3,Dados!$C$2:$C$1000,12))
A37: XTB | B37: =IF(COUNTIFS(Dados!$A$2:$A$1000,$B$3,Dados!$C$2:$C$1000,1,Dados!$E$2:$E$1000,"XTB")=0,"",SUMIFS(Dados!$F$2:$F$1000,Dados!$D$2:$D$1000,"Investimento",Dados!$E$2:$E$1000,"XTB",Dados!$A$2:$A$1000,$B$3,Dados!$C$2:$C$1000,1)) -> 157.01 | C37: =IF(COUNTIFS(Dados!$A$2:$A$1000,$B$3,Dados!$C$2:$C$1000,2,Dados!$E$2:$E$1000,"XTB")=0,"",SUMIFS(Dados!$F$2:$F$1000,Dados!$D$2:$D$1000,"Investimento",Dados!$E$2:$E$1000,"XTB",Dados!$A$2:$A$1000,$B$3,Dados!$C$2:$C$1000,2)) -> 213.06 | D37: =IF(COUNTIFS(Dados!$A$2:$A$1000,$B$3,Dados!$C$2:$C$1000,3,Dados!$E$2:$E$1000,"XTB")=0,"",SUMIFS(Dados!$F$2:$F$1000,Dados!$D$2:$D$1000,"Investimento",Dados!$E$2:$E$1000,"XTB",Dados!$A$2:$A$1000,$B$3,Dados!$C$2:$C$1000,3)) -> 203.32 | E37: =IF(COUNTIFS(Dados!$A$2:$A$1000,$B$3,Dados!$C$2:$C$1000,4,Dados!$E$2:$E$1000,"XTB")=0,"",SUMIFS(Dados!$F$2:$F$1000,Dados!$D$2:$D$1000,"Investimento",Dados!$E$2:$E$1000,"XTB",Dados!$A$2:$A$1000,$B$3,Dados!$C$2:$C$1000,4)) -> 262.41 | F37: =IF(COUNTIFS(Dados!$A$2:$A$1000,$B$3,Dados!$C$2:$C$1000,5,Dados!$E$2:$E$1000,"XTB")=0,"",SUMIFS(Dados!$F$2:$F$1000,Dados!$D$2:$D$1000,"Investimento",Dados!$E$2:$E$1000,"XTB",Dados!$A$2:$A$1000,$B$3,Dados!$C$2:$C$1000,5)) -> 329.06 | G37: =IF(COUNTIFS(Dados!$A$2:$A$1000,$B$3,Dados!$C$2:$C$1000,6,Dados!$E$2:$E$1000,"XTB")=0,"",SUMIFS(Dados!$F$2:$F$1000,Dados!$D$2:$D$1000,"Investimento",Dados!$E$2:$E$1000,"XTB",Dados!$A$2:$A$1000,$B$3,Dados!$C$2:$C$1000,6)) | H37: =IF(COUNTIFS(Dados!$A$2:$A$1000,$B$3,Dados!$C$2:$C$1000,7,Dados!$E$2:$E$1000,"XTB")=0,"",SUMIFS(Dados!$F$2:$F$1000,Dados!$D$2:$D$1000,"Investimento",Dados!$E$2:$E$1000,"XTB",Dados!$A$2:$A$1000,$B$3,Dados!$C$2:$C$1000,7)) -> 422.2 | I37: =IF(COUNTIFS(Dados!$A$2:$A$1000,$B$3,Dados!$C$2:$C$1000,8,Dados!$E$2:$E$1000,"XTB")=0,"",SUMIFS(Dados!$F$2:$F$1000,Dados!$D$2:$D$1000,"Investimento",Dados!$E$2:$E$1000,"XTB",Dados!$A$2:$A$1000,$B$3,Dados!$C$2:$C$1000,8)) -> 480.4 | J37: =IF(COUNTIFS(Dados!$A$2:$A$1000,$B$3,Dados!$C$2:$C$1000,9,Dados!$E$2:$E$1000,"XTB")=0,"",SUMIFS(Dados!$F$2:$F$1000,Dados!$D$2:$D$1000,"Investimento",Dados!$E$2:$E$1000,"XTB",Dados!$A$2:$A$1000,$B$3,Dados!$C$2:$C$1000,9)) | K37: =IF(COUNTIFS(Dados!$A$2:$A$1000,$B$3,Dados!$C$2:$C$1000,10,Dados!$E$2:$E$1000,"XTB")=0,"",SUMIFS(Dados!$F$2:$F$1000,Dados!$D$2:$D$1000,"Investimento",Dados!$E$2:$E$1000,"XTB",Dados!$A$2:$A$1000,$B$3,Dados!$C$2:$C$1000,10)) | L37: =IF(COUNTIFS(Dados!$A$2:$A$1000,$B$3,Dados!$C$2:$C$1000,11,Dados!$E$2:$E$1000,"XTB")=0,"",SUMIFS(Dados!$F$2:$F$1000,Dados!$D$2:$D$1000,"Investimento",Dados!$E$2:$E$1000,"XTB",Dados!$A$2:$A$1000,$B$3,Dados!$C$2:$C$1000,11)) | M37: =IF(COUNTIFS(Dados!$A$2:$A$1000,$B$3,Dados!$C$2:$C$1000,12,Dados!$E$2:$E$1000,"XTB")=0,"",SUMIFS(Dados!$F$2:$F$1000,Dados!$D$2:$D$1000,"Investimento",Dados!$E$2:$E$1000,"XTB",Dados!$A$2:$A$1000,$B$3,Dados!$C$2:$C$1000,12))
A40: Resumo por plataforma (mês mais recente)
A41: Plataforma | B41: Saldo atual | C41: Investido acumulado | D41: Ganho/Perda acumulado | E41: Alocação %
A42: Activobank | B42: =SUMIFS(Dados!$F$2:$F$1000,Dados!$D$2:$D$1000,"Investimento",Dados!$E$2:$E$1000,"Activobank",Dados!$A$2:$A$1000,$B$3,Dados!$C$2:$C$1000,$B$4) -> 100 | C42: =SUMIFS(Dados!$G$2:$G$1000,Dados!$D$2:$D$1000,"Investimento",Dados!$E$2:$E$1000,"Activobank",Dados!$A$2:$A$1000,$B$3) -> 0 | D42: =SUMIFS(Dados!$H$2:$H$1000,Dados!$D$2:$D$1000,"Investimento",Dados!$E$2:$E$1000,"Activobank",Dados!$A$2:$A$1000,$B$3) -> -3900 | E42: =IFERROR(B42/$B$51,"") -> 0.0027061117
A43: Bondora Go & Grow | B43: =SUMIFS(Dados!$F$2:$F$1000,Dados!$D$2:$D$1000,"Investimento",Dados!$E$2:$E$1000,"Bondora Go & Grow",Dados!$A$2:$A$1000,$B$3,Dados!$C$2:$C$1000,$B$4) -> 7089.2 | C43: =SUMIFS(Dados!$G$2:$G$1000,Dados!$D$2:$D$1000,"Investimento",Dados!$E$2:$E$1000,"Bondora Go & Grow",Dados!$A$2:$A$1000,$B$3) -> 522 | D43: =SUMIFS(Dados!$H$2:$H$1000,Dados!$D$2:$D$1000,"Investimento",Dados!$E$2:$E$1000,"Bondora Go & Grow",Dados!$A$2:$A$1000,$B$3) -> 315.91 | E43: =IFERROR(B43/$B$51,"") -> 0.19184167
A44: Degiro | B44: =SUMIFS(Dados!$F$2:$F$1000,Dados!$D$2:$D$1000,"Investimento",Dados!$E$2:$E$1000,"Degiro",Dados!$A$2:$A$1000,$B$3,Dados!$C$2:$C$1000,$B$4) -> 2430.88 | C44: =SUMIFS(Dados!$G$2:$G$1000,Dados!$D$2:$D$1000,"Investimento",Dados!$E$2:$E$1000,"Degiro",Dados!$A$2:$A$1000,$B$3) -> 200 | D44: =SUMIFS(Dados!$H$2:$H$1000,Dados!$D$2:$D$1000,"Investimento",Dados!$E$2:$E$1000,"Degiro",Dados!$A$2:$A$1000,$B$3) -> 220.05 | E44: =IFERROR(B44/$B$51,"") -> 0.065782327
A45: Golden SGF | B45: =SUMIFS(Dados!$F$2:$F$1000,Dados!$D$2:$D$1000,"Investimento",Dados!$E$2:$E$1000,"Golden SGF",Dados!$A$2:$A$1000,$B$3,Dados!$C$2:$C$1000,$B$4) -> 2991.1 | C45: =SUMIFS(Dados!$G$2:$G$1000,Dados!$D$2:$D$1000,"Investimento",Dados!$E$2:$E$1000,"Golden SGF",Dados!$A$2:$A$1000,$B$3) -> 300 | D45: =SUMIFS(Dados!$H$2:$H$1000,Dados!$D$2:$D$1000,"Investimento",Dados!$E$2:$E$1000,"Golden SGF",Dados!$A$2:$A$1000,$B$3) -> 187.41 | E45: =IFERROR(B45/$B$51,"") -> 0.080942506
A46: IGCP | B46: =SUMIFS(Dados!$F$2:$F$1000,Dados!$D$2:$D$1000,"Investimento",Dados!$E$2:$E$1000,"IGCP",Dados!$A$2:$A$1000,$B$3,Dados!$C$2:$C$1000,$B$4) -> 2741.98 | C46: =SUMIFS(Dados!$G$2:$G$1000,Dados!$D$2:$D$1000,"Investimento",Dados!$E$2:$E$1000,"IGCP",Dados!$A$2:$A$1000,$B$3) -> 0 | D46: =SUMIFS(Dados!$H$2:$H$1000,Dados!$D$2:$D$1000,"Investimento",Dados!$E$2:$E$1000,"IGCP",Dados!$A$2:$A$1000,$B$3) -> 34.55 | E46: =IFERROR(B46/$B$51,"") -> 0.074201041
A47: PPR Santander | B47: =SUMIFS(Dados!$F$2:$F$1000,Dados!$D$2:$D$1000,"Investimento",Dados!$E$2:$E$1000,"PPR Santander",Dados!$A$2:$A$1000,$B$3,Dados!$C$2:$C$1000,$B$4) -> 2048.85 | C47: =SUMIFS(Dados!$G$2:$G$1000,Dados!$D$2:$D$1000,"Investimento",Dados!$E$2:$E$1000,"PPR Santander",Dados!$A$2:$A$1000,$B$3) -> 300 | D47: =SUMIFS(Dados!$H$2:$H$1000,Dados!$D$2:$D$1000,"Investimento",Dados!$E$2:$E$1000,"PPR Santander",Dados!$A$2:$A$1000,$B$3) -> 39.64 | E47: =IFERROR(B47/$B$51,"") -> 0.055444169
A48: Revolut | B48: =SUMIFS(Dados!$F$2:$F$1000,Dados!$D$2:$D$1000,"Investimento",Dados!$E$2:$E$1000,"Revolut",Dados!$A$2:$A$1000,$B$3,Dados!$C$2:$C$1000,$B$4) -> 373.46 | C48: =SUMIFS(Dados!$G$2:$G$1000,Dados!$D$2:$D$1000,"Investimento",Dados!$E$2:$E$1000,"Revolut",Dados!$A$2:$A$1000,$B$3) -> 100 | D48: =SUMIFS(Dados!$H$2:$H$1000,Dados!$D$2:$D$1000,"Investimento",Dados!$E$2:$E$1000,"Revolut",Dados!$A$2:$A$1000,$B$3) -> 47.33 | E48: =IFERROR(B48/$B$51,"") -> 0.010106245
...

Sheet Registo Mensal
A1: Registo do mês
A3: Ano | B3: 2026
A4: Mês (nº 1-12) | B4: 9
A5: Mês | B5: =INDEX({"Janeiro";"Fevereiro";"Março";"Abril";"Maio";"Junho";"Julho";"Agosto";"Setembro";"Outubro";"Novembro";"Dezembro"},$B$4) -> Setembro
A7: Como usar: 1) preenche o Ano e o nº do mês acima. 2) Preenche a coluna Saldo (e Investido, só nas linhas de Investimento) para cada ativo. 3) O Ganho/Perda calcula-se sozinho. 4) Seleciona o intervalo A10:H21 (SEM o cabeçalho da linha 9), copia, e cola como VALORES (Ctrl+Shift+V no LibreOffice) na primeira linha livre da tabela 'Dados'. Só depois disso podes mudar o nº do mês aqui para o mês seguinte.
A9: Ano | B9: Mês | C9: MêsNum | D9: Categoria | E9: Ativo | F9: Saldo | G9: Investido | H9: Ganho/Perda
A10: =$B$3 -> 2026 | B10: =$B$5 -> Setembro | C10: =$B$4 -> 9 | D10: Conta Principal | E10: Conta Principal | H10: =IF(D10<>"Investimento","",IF(SUMPRODUCT(MAX((Dados!$E$2:$E$1000=E10)*((Dados!$A$2:$A$1000*100+Dados!$C$2:$C$1000)<($B$3*100+C10))*(Dados!$A$2:$A$1000*100+Dados!$C$2:$C$1000)))=0,"",F10-SUMPRODUCT((Dados!$E$2:$E$1000=E10)*((Dados!$A$2:$A$1000*100+Dados!$C$2:$C$1000)=SUMPRODUCT(MAX((Dados!$E$2:$E$1000=E10)*((Dados!$A$2:$A$1000*100+Dados!$C$2:$C$1000)<($B$3*100+C10))*(Dados!$A$2:$A$1000*100+Dados!$C$2:$C$1000))))*Dados!$F$2:$F$1000)-G10))
A11: =$B$3 -> 2026 | B11: =$B$5 -> Setembro | C11: =$B$4 -> 9 | D11: Investimento | E11: Activobank | H11: =IF(D11<>"Investimento","",IF(SUMPRODUCT(MAX((Dados!$E$2:$E$1000=E11)*((Dados!$A$2:$A$1000*100+Dados!$C$2:$C$1000)<($B$3*100+C11))*(Dados!$A$2:$A$1000*100+Dados!$C$2:$C$1000)))=0,"",F11-SUMPRODUCT((Dados!$E$2:$E$1000=E11)*((Dados!$A$2:$A$1000*100+Dados!$C$2:$C$1000)=SUMPRODUCT(MAX((Dados!$E$2:$E$1000=E11)*((Dados!$A$2:$A$1000*100+Dados!$C$2:$C$1000)<($B$3*100+C11))*(Dados!$A$2:$A$1000*100+Dados!$C$2:$C$1000))))*Dados!$F$2:$F$1000)-G11)) -> -100
A12: =$B$3 -> 2026 | B12: =$B$5 -> Setembro | C12: =$B$4 -> 9 | D12: Investimento | E12: Bondora Go & Grow | H12: =IF(D12<>"Investimento","",IF(SUMPRODUCT(MAX((Dados!$E$2:$E$1000=E12)*((Dados!$A$2:$A$1000*100+Dados!$C$2:$C$1000)<($B$3*100+C12))*(Dados!$A$2:$A$1000*100+Dados!$C$2:$C$1000)))=0,"",F12-SUMPRODUCT((Dados!$E$2:$E$1000=E12)*((Dados!$A$2:$A$1000*100+Dados!$C$2:$C$1000)=SUMPRODUCT(MAX((Dados!$E$2:$E$1000=E12)*((Dados!$A$2:$A$1000*100+Dados!$C$2:$C$1000)<($B$3*100+C12))*(Dados!$A$2:$A$1000*100+Dados!$C$2:$C$1000))))*Dados!$F$2:$F$1000)-G12)) -> -7089.2
A13: =$B$3 -> 2026 | B13: =$B$5 -> Setembro | C13: =$B$4 -> 9 | D13: Investimento | E13: Degiro | H13: =IF(D13<>"Investimento","",IF(SUMPRODUCT(MAX((Dados!$E$2:$E$1000=E13)*((Dados!$A$2:$A$1000*100+Dados!$C$2:$C$1000)<($B$3*100+C13))*(Dados!$A$2:$A$1000*100+Dados!$C$2:$C$1000)))=0,"",F13-SUMPRODUCT((Dados!$E$2:$E$1000=E13)*((Dados!$A$2:$A$1000*100+Dados!$C$2:$C$1000)=SUMPRODUCT(MAX((Dados!$E$2:$E$1000=E13)*((Dados!$A$2:$A$1000*100+Dados!$C$2:$C$1000)<($B$3*100+C13))*(Dados!$A$2:$A$1000*100+Dados!$C$2:$C$1000))))*Dados!$F$2:$F$1000)-G13)) -> -2430.88
A14: =$B$3 -> 2026 | B14: =$B$5 -> Setembro | C14: =$B$4 -> 9 | D14: Investimento | E14: Golden SGF | H14: =IF(D14<>"Investimento","",IF(SUMPRODUCT(MAX((Dados!$E$2:$E$1000=E14)*((Dados!$A$2:$A$1000*100+Dados!$C$2:$C$1000)<($B$3*100+C14))*(Dados!$A$2:$A$1000*100+Dados!$C$2:$C$1000)))=0,"",F14-SUMPRODUCT((Dados!$E$2:$E$1000=E14)*((Dados!$A$2:$A$1000*100+Dados!$C$2:$C$1000)=SUMPRODUCT(MAX((Dados!$E$2:$E$1000=E14)*((Dados!$A$2:$A$1000*100+Dados!$C$2:$C$1000)<($B$3*100+C14))*(Dados!$A$2:$A$1000*100+Dados!$C$2:$C$1000))))*Dados!$F$2:$F$1000)-G14)) -> -2991.1
A15: =$B$3 -> 2026 | B15: =$B$5 -> Setembro | C15: =$B$4 -> 9 | D15: Investimento | E15: IGCP | H15: =IF(D15<>"Investimento","",IF(SUMPRODUCT(MAX((Dados!$E$2:$E$1000=E15)*((Dados!$A$2:$A$1000*100+Dados!$C$2:$C$1000)<($B$3*100+C15))*(Dados!$A$2:$A$1000*100+Dados!$C$2:$C$1000)))=0,"",F15-SUMPRODUCT((Dados!$E$2:$E$1000=E15)*((Dados!$A$2:$A$1000*100+Dados!$C$2:$C$1000)=SUMPRODUCT(MAX((Dados!$E$2:$E$1000=E15)*((Dados!$A$2:$A$1000*100+Dados!$C$2:$C$1000)<($B$3*100+C15))*(Dados!$A$2:$A$1000*100+Dados!$C$2:$C$1000))))*Dados!$F$2:$F$1000)-G15)) -> -2741.98
A16: =$B$3 -> 2026 | B16: =$B$5 -> Setembro | C16: =$B$4 -> 9 | D16: Investimento | E16: PPR Santander | H16: =IF(D16<>"Investimento","",IF(SUMPRODUCT(MAX((Dados!$E$2:$E$1000=E16)*((Dados!$A$2:$A$1000*100+Dados!$C$2:$C$1000)<($B$3*100+C16))*(Dados!$A$2:$A$1000*100+Dados!$C$2:$C$1000)))=0,"",F16-SUMPRODUCT((Dados!$E$2:$E$1000=E16)*((Dados!$A$2:$A$1000*100+Dados!$C$2:$C$1000)=SUMPRODUCT(MAX((Dados!$E$2:$E$1000=E16)*((Dados!$A$2:$A$1000*100+Dados!$C$2:$C$1000)<($B$3*100+C16))*(Dados!$A$2:$A$1000*100+Dados!$C$2:$C$1000))))*Dados!$F$2:$F$1000)-G16)) -> -2048.85
A17: =$B$3 -> 2026 | B17: =$B$5 -> Setembro | C17: =$B$4 -> 9 | D17: Investimento | E17: Revolut | H17: =IF(D17<>"Investimento","",IF(SUMPRODUCT(MAX((Dados!$E$2:$E$1000=E17)*((Dados!$A$2:$A$1000*100+Dados!$C$2:$C$1000)<($B$3*100+C17))*(Dados!$A$2:$A$1000*100+Dados!$C$2:$C$1000)))=0,"",F17-SUMPRODUCT((Dados!$E$2:$E$1000=E17)*((Dados!$A$2:$A$1000*100+Dados!$C$2:$C$1000)=SUMPRODUCT(MAX((Dados!$E$2:$E$1000=E17)*((Dados!$A$2:$A$1000*100+Dados!$C$2:$C$1000)<($B$3*100+C17))*(Dados!$A$2:$A$1000*100+Dados!$C$2:$C$1000))))*Dados!$F$2:$F$1000)-G17)) -> -373.46
A18: =$B$3 -> 2026 | B18: =$B$5 -> Setembro | C18: =$B$4 -> 9 | D18: Investimento | E18: Trade Republic | H18: =IF(D18<>"Investimento","",IF(SUMPRODUCT(MAX((Dados!$E$2:$E$1000=E18)*((Dados!$A$2:$A$1000*100+Dados!$C$2:$C$1000)<($B$3*100+C18))*(Dados!$A$2:$A$1000*100+Dados!$C$2:$C$1000)))=0,"",F18-SUMPRODUCT((Dados!$E$2:$E$1000=E18)*((Dados!$A$2:$A$1000*100+Dados!$C$2:$C$1000)=SUMPRODUCT(MAX((Dados!$E$2:$E$1000=E18)*((Dados!$A$2:$A$1000*100+Dados!$C$2:$C$1000)<($B$3*100+C18))*(Dados!$A$2:$A$1000*100+Dados!$C$2:$C$1000))))*Dados!$F$2:$F$1000)-G18)) -> -18697.52
A19: =$B$3 -> 2026 | B19: =$B$5 -> Setembro | C19: =$B$4 -> 9 | D19: Investimento | E19: XTB | H19: =IF(D19<>"Investimento","",IF(SUMPRODUCT(MAX((Dados!$E$2:$E$1000=E19)*((Dados!$A$2:$A$1000*100+Dados!$C$2:$C$1000)<($B$3*100+C19))*(Dados!$A$2:$A$1000*100+Dados!$C$2:$C$1000)))=0,"",F19-SUMPRODUCT((Dados!$E$2:$E$1000=E19)*((Dados!$A$2:$A$1000*100+Dados!$C$2:$C$1000)=SUMPRODUCT(MAX((Dados!$E$2:$E$1000=E19)*((Dados!$A$2:$A$1000*100+Dados!$C$2:$C$1000)<($B$3*100+C19))*(Dados!$A$2:$A$1000*100+Dados!$C$2:$C$1000))))*Dados!$F$2:$F$1000)-G19)) -> -480.4
A20: =$B$3 -> 2026 | B20: =$B$5 -> Setembro | C20: =$B$4 -> 9 | D20: Numerário | E20: Numerário (dinheiro em casa) | H20: =IF(D20<>"Investimento","",IF(SUMPRODUCT(MAX((Dados!$E$2:$E$1000=E20)*((Dados!$A$2:$A$1000*100+Dados!$C$2:$C$1000)<($B$3*100+C20))*(Dados!$A$2:$A$1000*100+Dados!$C$2:$C$1000)))=0,"",F20-SUMPRODUCT((Dados!$E$2:$E$1000=E20)*((Dados!$A$2:$A$1000*100+Dados!$C$2:$C$1000)=SUMPRODUCT(MAX((Dados!$E$2:$E$1000=E20)*((Dados!$A$2:$A$1000*100+Dados!$C$2:$C$1000)<($B$3*100+C20))*(Dados!$A$2:$A$1000*100+Dados!$C$2:$C$1000))))*Dados!$F$2:$F$1000)-G20))
A21: =$B$3 -> 2026 | B21: =$B$5 -> Setembro | C21: =$B$4 -> 9 | D21: Criptoativo | E21: Bitcoin | H21: =IF(D21<>"Investimento","",IF(SUMPRODUCT(MAX((Dados!$E$2:$E$1000=E21)*((Dados!$A$2:$A$1000*100+Dados!$C$2:$C$1000)<($B$3*100+C21))*(Dados!$A$2:$A$1000*100+Dados!$C$2:$C$1000)))=0,"",F21-SUMPRODUCT((Dados!$E$2:$E$1000=E21)*((Dados!$A$2:$A$1000*100+Dados!$C$2:$C$1000)=SUMPRODUCT(MAX((Dados!$E$2:$E$1000=E21)*((Dados!$A$2:$A$1000*100+Dados!$C$2:$C$1000)<($B$3*100+C21))*(Dados!$A$2:$A$1000*100+Dados!$C$2:$C$1000))))*Dados!$F$2:$F$1000)-G21))

Sheet Dados
A1: Ano | B1: Mês | C1: MêsNum | D1: Categoria | E1: Ativo | F1: Saldo | G1: Investido | H1: Ganho/Perda | J1: Nota: dados migrados do formato largo original (folha '2026 (formato antigo)'). Corrigido nesta migração: o total de Janeiro/2026 excluía a XTB (bug na fórmula original =SUM(B8:B16)); nesta tabela os totais são sempre calculados por SUMIFS, por isso esse tipo de erro deixa de poder acontecer.
A2: 2026 | B2: Janeiro | C2: 1 | D2: Conta Principal | E2: Conta Principal | F2: 1670.18 | H2: =IF(D2<>"Investimento","",IF(SUMPRODUCT(MAX(($E$2:$E$1000=E2)*(($A$2:$A$1000*100+$C$2:$C$1000)<(A2*100+C2))*($A$2:$A$1000*100+$C$2:$C$1000)))=0,"",F2-SUMPRODUCT(($E$2:$E$1000=E2)*(($A$2:$A$1000*100+$C$2:$C$1000)=SUMPRODUCT(MAX(($E$2:$E$1000=E2)*(($A$2:$A$1000*100+$C$2:$C$1000)<(A2*100+C2))*($A$2:$A$1000*100+$C$2:$C$1000))))*$F$2:$F$1000)-G2))
A3: 2026 | B3: Janeiro | C3: 1 | D3: Investimento | E3: Activobank | F3: 4000 | H3: =IF(D3<>"Investimento","",IF(SUMPRODUCT(MAX(($E$2:$E$1000=E3)*(($A$2:$A$1000*100+$C$2:$C$1000)<(A3*100+C3))*($A$2:$A$1000*100+$C$2:$C$1000)))=0,"",F3-SUMPRODUCT(($E$2:$E$1000=E3)*(($A$2:$A$1000*100+$C$2:$C$1000)=SUMPRODUCT(MAX(($E$2:$E$1000=E3)*(($A$2:$A$1000*100+$C$2:$C$1000)<(A3*100+C3))*($A$2:$A$1000*100+$C$2:$C$1000))))*$F$2:$F$1000)-G3))
A4: 2026 | B4: Janeiro | C4: 1 | D4: Investimento | E4: Bondora Go & Grow | F4: 6251.29 | H4: =IF(D4<>"Investimento","",IF(SUMPRODUCT(MAX(($E$2:$E$1000=E4)*(($A$2:$A$1000*100+$C$2:$C$1000)<(A4*100+C4))*($A$2:$A$1000*100+$C$2:$C$1000)))=0,"",F4-SUMPRODUCT(($E$2:$E$1000=E4)*(($A$2:$A$1000*100+$C$2:$C$1000)=SUMPRODUCT(MAX(($E$2:$E$1000=E4)*(($A$2:$A$1000*100+$C$2:$C$1000)<(A4*100+C4))*($A$2:$A$1000*100+$C$2:$C$1000))))*$F$2:$F$1000)-G4))
A5: 2026 | B5: Janeiro | C5: 1 | D5: Investimento | E5: Degiro | F5: 2010.83 | H5: =IF(D5<>"Investimento","",IF(SUMPRODUCT(MAX(($E$2:$E$1000=E5)*(($A$2:$A$1000*100+$C$2:$C$1000)<(A5*100+C5))*($A$2:$A$1000*100+$C$2:$C$1000)))=0,"",F5-SUMPRODUCT(($E$2:$E$1000=E5)*(($A$2:$A$1000*100+$C$2:$C$1000)=SUMPRODUCT(MAX(($E$2:$E$1000=E5)*(($A$2:$A$1000*100+$C$2:$C$1000)<(A5*100+C5))*($A$2:$A$1000*100+$C$2:$C$1000))))*$F$2:$F$1000)-G5))
A6: 2026 | B6: Janeiro | C6: 1 | D6: Investimento | E6: Golden SGF | F6: 2503.69 | H6: =IF(D6<>"Investimento","",IF(SUMPRODUCT(MAX(($E$2:$E$1000=E6)*(($A$2:$A$1000*100+$C$2:$C$1000)<(A6*100+C6))*($A$2:$A$1000*100+$C$2:$C$1000)))=0,"",F6-SUMPRODUCT(($E$2:$E$1000=E6)*(($A$2:$A$1000*100+$C$2:$C$1000)=SUMPRODUCT(MAX(($E$2:$E$1000=E6)*(($A$2:$A$1000*100+$C$2:$C$1000)<(A6*100+C6))*($A$2:$A$1000*100+$C$2:$C$1000))))*$F$2:$F$1000)-G6))
A7: 2026 | B7: Janeiro | C7: 1 | D7: Investimento | E7: IGCP | F7: 2707.43 | H7: =IF(D7<>"Investimento","",IF(SUMPRODUCT(MAX(($E$2:$E$1000=E7)*(($A$2:$A$1000*100+$C$2:$C$1000)<(A7*100+C7))*($A$2:$A$1000*100+$C$2:$C$1000)))=0,"",F7-SUMPRODUCT(($E$2:$E$1000=E7)*(($A$2:$A$1000*100+$C$2:$C$1000)=SUMPRODUCT(MAX(($E$2:$E$1000=E7)*(($A$2:$A$1000*100+$C$2:$C$1000)<(A7*100+C7))*($A$2:$A$1000*100+$C$2:$C$1000))))*$F$2:$F$1000)-G7))
A8: 2026 | B8: Janeiro | C8: 1 | D8: Investimento | E8: PPR Santander | F8: 1709.21 | H8: =IF(D8<>"Investimento","",IF(SUMPRODUCT(MAX(($E$2:$E$1000=E8)*(($A$2:$A$1000*100+$C$2:$C$1000)<(A8*100+C8))*($A$2:$A$1000*100+$C$2:$C$1000)))=0,"",F8-SUMPRODUCT(($E$2:$E$1000=E8)*(($A$2:$A$1000*100+$C$2:$C$1000)=SUMPRODUCT(MAX(($E$2:$E$1000=E8)*(($A$2:$A$1000*100+$C$2:$C$1000)<(A8*100+C8))*($A$2:$A$1000*100+$C$2:$C$1000))))*$F$2:$F$1000)-G8))
A9: 2026 | B9: Janeiro | C9: 1 | D9: Investimento | E9: Revolut | F9: 226.13 | H9: =IF(D9<>"Investimento","",IF(SUMPRODUCT(MAX(($E$2:$E$1000=E9)*(($A$2:$A$1000*100+$C$2:$C$1000)<(A9*100+C9))*($A$2:$A$1000*100+$C$2:$C$1000)))=0,"",F9-SUMPRODUCT(($E$2:$E$1000=E9)*(($A$2:$A$1000*100+$C$2:$C$1000)=SUMPRODUCT(MAX(($E$2:$E$1000=E9)*(($A$2:$A$1000*100+$C$2:$C$1000)<(A9*100+C9))*($A$2:$A$1000*100+$C$2:$C$1000))))*$F$2:$F$1000)-G9))
A10: 2026 | B10: Janeiro | C10: 1 | D10: Investimento | E10: Trade Republic | F10: 18991.73 | H10: =IF(D10<>"Investimento","",IF(SUMPRODUCT(MAX(($E$2:$E$1000=E10)*(($A$2:$A$1000*100+$C$2:$C$1000)<(A10*100+C10))*($A$2:$A$1000*100+$C$2:$C$1000)))=0,"",F10-SUMPRODUCT(($E$2:$E$1000=E10)*(($A$2:$A$1000*100+$C$2:$C$1000)=SUMPRODUCT(MAX(($E$2:$E$1000=E10)*(($A$2:$A$1000*100+$C$2:$C$1000)<(A10*100+C10))*($A$2:$A$1000*100+$C$2:$C$1000))))*$F$2:$F$1000)-G10))
A11: 2026 | B11: Janeiro | C11: 1 | D11: Investimento | E11: XTB | F11: 157.01 | H11: =IF(D11<>"Investimento","",IF(SUMPRODUCT(MAX(($E$2:$E$1000=E11)*(($A$2:$A$1000*100+$C$2:$C$1000)<(A11*100+C11))*($A$2:$A$1000*100+$C$2:$C$1000)))=0,"",F11-SUMPRODUCT(($E$2:$E$1000=E11)*(($A$2:$A$1000*100+$C$2:$C$1000)=SUMPRODUCT(MAX(($E$2:$E$1000=E11)*(($A$2:$A$1000*100+$C$2:$C$1000)<(A11*100+C11))*($A$2:$A$1000*100+$C$2:$C$1000))))*$F$2:$F$1000)-G11))
A12: 2026 | B12: Janeiro | C12: 1 | D12: Numerário | E12: Numerário (dinheiro em casa) | F12: 470 | H12: =IF(D12<>"Investimento","",IF(SUMPRODUCT(MAX(($E$2:$E$1000=E12)*(($A$2:$A$1000*100+$C$2:$C$1000)<(A12*100+C12))*($A$2:$A$1000*100+$C$2:$C$1000)))=0,"",F12-SUMPRODUCT(($E$2:$E$1000=E12)*(($A$2:$A$1000*100+$C$2:$C$1000)=SUMPRODUCT(MAX(($E$2:$E$1000=E12)*(($A$2:$A$1000*100+$C$2:$C$1000)<(A12*100+C12))*($A$2:$A$1000*100+$C$2:$C$1000))))*$F$2:$F$1000)-G12))
A13: 2026 | B13: Janeiro | C13: 1 | D13: Criptoativo | E13: Bitcoin | F13: 35.12 | H13: =IF(D13<>"Investimento","",IF(SUMPRODUCT(MAX(($E$2:$E$1000=E13)*(($A$2:$A$1000*100+$C$2:$C$1000)<(A13*100+C13))*($A$2:$A$1000*100+$C$2:$C$1000)))=0,"",F13-SUMPRODUCT(($E$2:$E$1000=E13)*(($A$2:$A$1000*100+$C$2:$C$1000)=SUMPRODUCT(MAX(($E$2:$E$1000=E13)*(($A$2:$A$1000*100+$C$2:$C$1000)<(A13*100+C13))*($A$2:$A$1000*100+$C$2:$C$1000))))*$F$2:$F$1000)-G13))
A14: 2026 | B14: Fevereiro | C14: 2 | D14: Conta Principal | E14: Conta Principal | F14: 2628.38 | H14: =IF(D14<>"Investimento","",IF(SUMPRODUCT(MAX(($E$2:$E$1000=E14)*(($A$2:$A$1000*100+$C$2:$C$1000)<(A14*100+C14))*($A$2:$A$1000*100+$C$2:$C$1000)))=0,"",F14-SUMPRODUCT(($E$2:$E$1000=E14)*(($A$2:$A$1000*100+$C$2:$C$1000)=SUMPRODUCT(MAX(($E$2:$E$1000=E14)*(($A$2:$A$1000*100+$C$2:$C$1000)<(A14*100+C14))*($A$2:$A$1000*100+$C$2:$C$1000))))*$F$2:$F$1000)-G14))
A15: 2026 | B15: Fevereiro | C15: 2 | D15: Investimento | E15: Activobank | F15: 267.71 | G15: 0 | H15: =IF(D15<>"Investimento","",IF(SUMPRODUCT(MAX(($E$2:$E$1000=E15)*(($A$2:$A$1000*100+$C$2:$C$1000)<(A15*100+C15))*($A$2:$A$1000*100+$C$2:$C$1000)))=0,"",F15-SUMPRODUCT(($E$2:$E$1000=E15)*(($A$2:$A$1000*100+$C$2:$C$1000)=SUMPRODUCT(MAX(($E$2:$E$1000=E15)*(($A$2:$A$1000*100+$C$2:$C$1000)<(A15*100+C15))*($A$2:$A$1000*100+$C$2:$C$1000))))*$F$2:$F$1000)-G15)) -> -3732.29
A16: 2026 | B16: Fevereiro | C16: 2 | D16: Investimento | E16: Bondora Go & Grow | F16: 6309.34 | G16: 26 | H16: =IF(D16<>"Investimento","",IF(SUMPRODUCT(MAX(($E$2:$E$1000=E16)*(($A$2:$A$1000*100+$C$2:$C$1000)<(A16*100+C16))*($A$2:$A$1000*100+$C$2:$C$1000)))=0,"",F16-SUMPRODUCT(($E$2:$E$1000=E16)*(($A$2:$A$1000*100+$C$2:$C$1000)=SUMPRODUCT(MAX(($E$2:$E$1000=E16)*(($A$2:$A$1000*100+$C$2:$C$1000)<(A16*100+C16))*($A$2:$A$1000*100+$C$2:$C$1000))))*$F$2:$F$1000)-G16)) -> 32.05
A17: 2026 | B17: Fevereiro | C17: 2 | D17: Investimento | E17: Degiro | F17: 2046.34 | G17: 0 | H17: =IF(D17<>"Investimento","",IF(SUMPRODUCT(MAX(($E$2:$E$1000=E17)*(($A$2:$A$1000*100+$C$2:$C$1000)<(A17*100+C17))*($A$2:$A$1000*100+$C$2:$C$1000)))=0,"",F17-SUMPRODUCT(($E$2:$E$1000=E17)*(($A$2:$A$1000*100+$C$2:$C$1000)=SUMPRODUCT(MAX(($E$2:$E$1000=E17)*(($A$2:$A$1000*100+$C$2:$C$1000)<(A17*100+C17))*($A$2:$A$1000*100+$C$2:$C$1000))))*$F$2:$F$1000)-G17)) -> 35.51
A18: 2026 | B18: Fevereiro | C18: 2 | D18: Investimento | E18: Golden SGF | F18: 2557.77 | G18: 50 | H18: =IF(D18<>"Investimento","",IF(SUMPRODUCT(MAX(($E$2:$E$1000=E18)*(($A$2:$A$1000*100+$C$2:$C$1000)<(A18*100+C18))*($A$2:$A$1000*100+$C$2:$C$1000)))=0,"",F18-SUMPRODUCT(($E$2:$E$1000=E18)*(($A$2:$A$1000*100+$C$2:$C$1000)=SUMPRODUCT(MAX(($E$2:$E$1000=E18)*(($A$2:$A$1000*100+$C$2:$C$1000)<(A18*100+C18))*($A$2:$A$1000*100+$C$2:$C$1000))))*$F$2:$F$1000)-G18)) -> 4.08
A19: 2026 | B19: Fevereiro | C19: 2 | D19: Investimento | E19: IGCP | F19: 2707.43 | G19: 0 | H19: =IF(D19<>"Investimento","",IF(SUMPRODUCT(MAX(($E$2:$E$1000=E19)*(($A$2:$A$1000*100+$C$2:$C$1000)<(A19*100+C19))*($A$2:$A$1000*100+$C$2:$C$1000)))=0,"",F19-SUMPRODUCT(($E$2:$E$1000=E19)*(($A$2:$A$1000*100+$C$2:$C$1000)=SUMPRODUCT(MAX(($E$2:$E$1000=E19)*(($A$2:$A$1000*100+$C$2:$C$1000)<(A19*100+C19))*($A$2:$A$1000*100+$C$2:$C$1000))))*$F$2:$F$1000)-G19)) -> 0
A20: 2026 | B20: Fevereiro | C20: 2 | D20: Investimento | E20: PPR Santander | F20: 1766 | G20: 50 | H20: =IF(D20<>"Investimento","",IF(SUMPRODUCT(MAX(($E$2:$E$1000=E20)*(($A$2:$A$1000*100+$C$2:$C$1000)<(A20*100+C20))*($A$2:$A$1000*100+$C$2:$C$1000)))=0,"",F20-SUMPRODUCT(($E$2:$E$1000=E20)*(($A$2:$A$1000*100+$C$2:$C$1000)=SUMPRODUCT(MAX(($E$2:$E$1000=E20)*(($A$2:$A$1000*100+$C$2:$C$1000)<(A20*100+C20))*($A$2:$A$1000*100+$C$2:$C$1000))))*$F$2:$F$1000)-G20)) -> 6.79
A21: 2026 | B21: Fevereiro | C21: 2 | D21: Investimento | E21: Revolut | F21: 246.28 | G21: 20 | H21: =IF(D21<>"Investimento","",IF(SUMPRODUCT(MAX(($E$2:$E$1000=E21)*(($A$2:$A$1000*100+$C$2:$C$1000)<(A21*100+C21))*($A$2:$A$1000*100+$C$2:$C$1000)))=0,"",F21-SUMPRODUCT(($E$2:$E$1000=E21)*(($A$2:$A$1000*100+$C$2:$C$1000)=SUMPRODUCT(MAX(($E$2:$E$1000=E21)*(($A$2:$A$1000*100+$C$2:$C$1000)<(A21*100+C21))*($A$2:$A$1000*100+$C$2:$C$1000))))*$F$2:$F$1000)-G21)) -> 0.15
A22: 2026 | B22: Fevereiro | C22: 2 | D22: Investimento | E22: Trade Republic | F22: 18991.73 | G22: 0 | H22: =IF(D22<>"Investimento","",IF(SUMPRODUCT(MAX(($E$2:$E$1000=E22)*(($A$2:$A$1000*100+$C$2:$C$1000)<(A22*100+C22))*($A$2:$A$1000*100+$C$2:$C$1000)))=0,"",F22-SUMPRODUCT(($E$2:$E$1000=E22)*(($A$2:$A$1000*100+$C$2:$C$1000)=SUMPRODUCT(MAX(($E$2:$E$1000=E22)*(($A$2:$A$1000*100+$C$2:$C$1000)<(A22*100+C22))*($A$2:$A$1000*100+$C$2:$C$1000))))*$F$2:$F$1000)-G22)) -> 0
A23: 2026 | B23: Fevereiro | C23: 2 | D23: Investimento | E23: XTB | F23: 213.06 | G23: 50 | H23: =IF(D23<>"Investimento","",IF(SUMPRODUCT(MAX(($E$2:$E$1000=E23)*(($A$2:$A$1000*100+$C$2:$C$1000)<(A23*100+C23))*($A$2:$A$1000*100+$C$2:$C$1000)))=0,"",F23-SUMPRODUCT(($E$2:$E$1000=E23)*(($A$2:$A$1000*100+$C$2:$C$1000)=SUMPRODUCT(MAX(($E$2:$E$1000=E23)*(($A$2:$A$1000*100+$C$2:$C$1000)<(A23*100+C23))*($A$2:$A$1000*100+$C$2:$C$1000))))*$F$2:$F$1000)-G23)) -> 6.05
A24: 2026 | B24: Fevereiro | C24: 2 | D24: Numerário | E24: Numerário (dinheiro em casa) | F24: 370 | H24: =IF(D24<>"Investimento","",IF(SUMPRODUCT(MAX(($E$2:$E$1000=E24)*(($A$2:$A$1000*100+$C$2:$C$1000)<(A24*100+C24))*($A$2:$A$1000*100+$C$2:$C$1000)))=0,"",F24-SUMPRODUCT(($E$2:$E$1000=E24)*(($A$2:$A$1000*100+$C$2:$C$1000)=SUMPRODUCT(MAX(($E$2:$E$1000=E24)*(($A$2:$A$1000*100+$C$2:$C$1000)<(A24*100+C24))*($A$2:$A$1000*100+$C$2:$C$1000))))*$F$2:$F$1000)-G24))
